Workbook

Sheet Comportamientos
A1: Fecha | B1: Bugs Totales | C1: Bugs Cancelados | D1: Bugs Solucionados | E1: Bugs Pendientes | F1: Incidentes UAT | G1: %Fuga | I1: Bugs Nuevos | J1: Bugs Solucionados | K1: Bugs Pendientes | L1: BUGS UAT
A2: 45993 | B2: 280 | C2: =B2-D2-E2 -> 36 | D2: 104 | E2: 140 | F2: 23 | G2: =F2/B2 -> 0.082142857
A3: 45999 | B3: 296 | C3: =B3-D3-E3 -> 36 | D3: 114 | E3: 146 | F3: 32 | G3: =F3/B3 -> 0.10810811 | I3: =B3-B2 -> 16 | J3: =D3-D2 -> 10 | K3: =E3-E2 -> 6 | L3: =F3-F2 -> 9
A4: 46006 | B4: 319 | C4: =B4-D4-E4 -> 46 | D4: 129 | E4: 144 | F4: 40 | G4: =F4/B4 -> 0.12539185 | I4: =B4-B3 -> 23 | J4: =D4-D3 -> 15 | K4: =E4-E3 -> -2 | L4: =F4-F3 -> 8
A5: 46013 | B5: 338 | C5: 56 | D5: 140 | E5: 142 | F5: 36 | G5: =F5/B5 -> 0.10650888 | I5: =B5-B4 -> 19 | J5: =D5-D4 -> 11 | K5: =E5-E4 -> -2 | L5: =F5-F4 -> -4
A6: 46020 | B6: 356 | C6: 56 | D6: 158 | E6: 142 | F6: 40 | G6: =F6/B6 -> 0.11235955 | I6: =B6-B5 -> 18 | J6: =D6-D5 -> 18 | K6: =E6-E5 -> 0 | L6: =F6-F5 -> 4
A7: 46027 | B7: 360 | C7: 56 | D7: 158 | E7: 146 | F7: 40 | G7: =F7/B7 -> 0.11111111 | I7: =B7-B6 -> 4 | J7: =D7-D6 -> 0 | K7: =E7-E6 -> 4 | L7: =F7-F6 -> 0
J9: =AVERAGE(J3:J6) -> 13.5
A13: % Fuga por prioridad
A14: Highest | B14: =C14/$F$7 -> 0.2 | C14: 8
A15: High | B15: =C15/$F$7 -> 0.325 | C15: 13
A16: Medium | B16: =C16/$F$7 -> 0.325 | C16: 13
A17: Low | B17: =C17/$F$7 -> 0.15 | C17: 6

Sheet fuga
A1: Fue encontrado durante UAT? | B1: SI
AD2: BUGS TOTALES | AE2: BUGS UAT
A3: Recuento de Fue encontrado durante UAT? | C3: Estado | Y3: VERSIÓN | Z3: %FUGA
A4: En que versión de UAT fue encontrado? | B4: Prioridad | C4: Blocked | D4: Cancelado | E4: READY FOR TESTING | F4: READY FOR UAT | G4: Tareas por hacer | H4: TO BE DEPLOYED-SIT | I4: Total general | Y4: 0.14 S1 | Z4: =AE4/AD4 -> 0.09623431 | AD4: 239 | AE4: 23
A5: UAT_V0.12 | C5: 1 | D5: 6 | F5: 9 | G5: 3 | I5: 19 | Y5: 0.14 S2 | Z5: =AE5/AD5 -> 0.10810811 | AD5: 296 | AE5: 32
A6: UAT_V0.13 | C6: 1 | D6: 1 | E6: 1 | G6: 5 | H6: 1 | I6: 9
A7: UAT_V0.14 | D7: 1 | F7: 6 | G7: 2 | I7: 9
A8: UAT_V0.15 | B8: Alta | G8: 1 | I8: 1
B9: Medio | G9: 2 | I9: 2
A10: UAT_V0.15 Total | G10: 3 | I10: 3
A11: Total general | C11: 2 | D11: 8 | E11: 1 | F11: 15 | G11: 13 | H11: 1 | I11: 40
A45: Fue encontrado durante UAT? | B45: SI
A47: Recuento de Prioridad | B47: Prioridad
A48: Estado | B48: Alta | C48: Baja | D48: Más alta | E48: Medio | F48: Total general
A49: Blocked | B49: 1 | E49: 1 | F49: 2
A50: READY FOR TESTING | B50: 1 | F50: 1
A51: READY FOR UAT | B51: 4 | C51: 3 | D51: 5 | E51: 3 | F51: 15
A52: Tareas por hacer | B52: 4 | D52: 3 | E52: 6 | F52: 13
A53: TO BE DEPLOYED-SIT | E53: 1 | F53: 1
A54: Total general | B54: 10 | C54: 3 | D54: 8 | E54: 11 | F54: 32
A71: % Fuga por prioridad
A72: Highest | B72: =C72/F54 -> 0.25 | C72: =D54 -> 8
A73: High | B73: =C73/F54 -> 0.3125 | C73: =B54 -> 10
A74: Medium | B74: =C74/F54 -> 0.34375 | C74: =E54 -> 11
A75: Low | B75: =C75/F54 -> 0.09375 | C75: =C54 -> 3

Sheet TendenciaXVersión
B3: Versión | C3: Bugs Encontrados | D3: % Casos de Prueba Fallidos | E3: BUGS Cancelados | F3: Bugs Solucionados | G3: BUGS Pendientes por Resolver | H3: % Bugs Pendientes por resolver
B4: 0.4 | C4: ='BUGS X VERSIÓN'!$B10 -> 35 | D4: =+#REF!/#REF! -> #REF! | E4: ='BUGS X VERSIÓN'!$B70 -> 7 | F4: ='BUGS X VERSIÓN'!$B98 -> 22 | G4: ='BUGS X VERSIÓN'!$B120 -> 6 | H4: =G4/C4 -> 0.17142857
B5: 0.5 | C5: ='BUGS X VERSIÓN'!$B11 -> 9 | D5: =+C4/#REF! -> #REF! | E5: ='BUGS X VERSIÓN'!$B71 -> 4 | F5: ='BUGS X VERSIÓN'!$B99 -> 5 | G5: 0 | H5: =G5/C5 -> 0
B6: 0.5.1 | C6: ='BUGS X VERSIÓN'!$B12 -> 10 | E6: ='BUGS X VERSIÓN'!$B72 -> 3 | F6: ='BUGS X VERSIÓN'!$B100 -> 6 | G6: ='BUGS X VERSIÓN'!$B121 -> 1 | H6: =G6/C6 -> 0.1
B7: 0.6 | C7: ='BUGS X VERSIÓN'!$B13 -> 27 | D7: =+C5/#REF! -> #REF! | E7: ='BUGS X VERSIÓN'!$B73 -> 1 | F7: ='BUGS X VERSIÓN'!$B101 -> 22 | G7: ='BUGS X VERSIÓN'!$B122 -> 4 | H7: =G7/C7 -> 0.14814815
B8: 0.6.1 | C8: ='BUGS X VERSIÓN'!$B14 -> 10 | E8: 0 | F8: ='BUGS X VERSIÓN'!$B102 -> 9 | G8: ='BUGS X VERSIÓN'!$B123 -> 1 | H8: =G8/C8 -> 0.1
B9: 0.7 | C9: ='BUGS X VERSIÓN'!$B15 -> 21 | D9: =+C7/#REF! -> #REF! | E9: ='BUGS X VERSIÓN'!$B$74 -> 2 | F9: ='BUGS X VERSIÓN'!$B103 -> 15 | G9: ='BUGS X VERSIÓN'!$B124 -> 4 | H9: =G9/C9 -> 0.19047619
B10: 0.8 | C10: ='BUGS X VERSIÓN'!$B16 -> 15 | D10: =+C9/#REF! -> #REF! | E10: ='BUGS X VERSIÓN'!$B$75 -> 5 | F10: ='BUGS X VERSIÓN'!$B89 -> 5 | G10: ='BUGS X VERSIÓN'!$B111 -> 5 | H10: =G10/C10 -> 0.33333333
B11: 0.9 | C11: ='BUGS X VERSIÓN'!$B17 -> 7 | E11: 0 | F11: ='BUGS X VERSIÓN'!$B90 -> 5 | G11: ='BUGS X VERSIÓN'!$B112 -> 2 | H11: =G11/C11 -> 0.28571429
B12: 0.1 | C12: ='BUGS X VERSIÓN'!$B4 -> 12 | E12: 0 | F12: ='BUGS X VERSIÓN'!$B91 -> 8 | G12: ='BUGS X VERSIÓN'!$B113 -> 4 | H12: =G12/C12 -> 0.33333333
B13: 0.10.1 | C13: ='BUGS X VERSIÓN'!$B5 -> 19 | E13: ='BUGS X VERSIÓN'!$B65 -> 2 | F13: ='BUGS X VERSIÓN'!$B92 -> 7 | G13: ='BUGS X VERSIÓN'!$B114 -> 10 | H13: =G13/C13 -> 0.52631579
B14: 0.11 | C14: ='BUGS X VERSIÓN'!$B6 -> 35 | D14: =+C13/#REF! -> #REF! | E14: ='BUGS X VERSIÓN'!$B66 -> 9 | F14: ='BUGS X VERSIÓN'!$B93 -> 8 | G14: ='BUGS X VERSIÓN'!$B115 -> 18 | H14: =G14/C14 -> 0.51428571
B15: 0.12 | C15: ='BUGS X VERSIÓN'!$B7 -> 51 | E15: ='BUGS X VERSIÓN'!$B67 -> 15 | F15: ='BUGS X VERSIÓN'!$B94 -> 18 | G15: ='BUGS X VERSIÓN'!$B116 -> 18 | H15: =G15/C15 -> 0.35294118
B16: 0.13 | C16: ='BUGS X VERSIÓN'!$B8 -> 24 | E16: ='BUGS X VERSIÓN'!$B$68 -> 1 | F16: ='BUGS X VERSIÓN'!$B95 -> 6 | G16: ='BUGS X VERSIÓN'!$B117 -> 17 | H16: =G16/C16 -> 0.70833333
B17: 0.14 | C17: ='BUGS X VERSIÓN'!$B9 -> 38 | E17: ='BUGS X VERSIÓN'!$B$69 -> 5 | F17: ='BUGS X VERSIÓN'!$B96 -> 15 | G17: ='BUGS X VERSIÓN'!$B118 -> 18 | H17: =G17/C17 -> 0.47368421
A18: En curso | B18: 0.15 | C18: 47 | E18: ='BUGS X VERSIÓN'!$B$76 -> 2 | F18: ='BUGS X VERSIÓN'!$B97 -> 7 | G18: 38 | H18: =G18/C18 -> 0.80851064
C19: =SUM(C4:C18) -> 360 | D19: =C19/#REF! -> #REF! | E19: =SUM(E4:E18) -> 56 | F19: =SUM(F4:F18) -> 158 | G19: =SUM(G4:G18) -> 146 | H19: =G19/C19 -> 0.40555556

Sheet BUGS X VERSIÓN
A1: Estado | B1: (Todas)
A3: ¿En qué versión fue encontrado? | B3: Recuento de Estado
A4: 0.10 | B4: 12
A5: 0.10.1 | B5: 19
A6: 0.11 | B6: 35
A7: 0.12 | B7: 51
A8: 0.13 | B8: 24
A9: 0.14 | B9: 38
A10: 0.4 | B10: 35
A11: 0.5 | B11: 9
A12: 0.5.1 | B12: 10
A13: 0.6 | B13: 27
A14: 0.6.1 | B14: 10
A15: 0.7 | B15: 21
... A19: Total general | B19: 360
A36: ¿En qué versión fue encontrado? | B36: Recuento de ¿En qué versión fue encontrado?
A37: V0.9 | B37: 7
A38: V0.8 | B38: 15
A39: V0.7 | B39: 21
A40: V0.6.1 | B40: 10
A41: V0.6 | B41: 27
A42: V0.5.1 | B42: 10
A43: V0.5 | B43: 9
A44: V0.4 | B44: 35
A45: V0.15 | B45: 47
A46: V0.14 | B46: 38
A47: V0.13 | B47: 24
A48: V0.12 | B48: 51
... A52: Total general | B52: 360
A59: BUGS CANCELADOS
A62: Estado | B62: Cancelado
A64: ¿En qué versión fue encontrado? | B64: Recuento de Estado
A65: 0.10.1 | B65: 2
A66: 0.11 | B66: 9
A67: 0.12 | B67: 15
A68: 0.13 | B68: 1 | H68: Cómo colocar lo que este en la columna B de la hoja Bugs x Versión si E de la hoja tendenciaXVersionen de un archivo coincide con A de la hoja Bugs x Versión
A69: 0.14 | B69: 5
A70: 0.4 | B70: 7
A71: 0.5 | B71: 4
A72: 0.5.1 | B72: 3
...

Sheet Reporte_Gral
A1: Tipo de Incidencia | B1: Clave de incidencia | C1: ID de la incidencia | D1: Resumen | E1: Prioridad | F1: Estado | G1: Sprint | H1: Sprint2 | I1: Sprint3 | J1: Sprint4 | K1: Sprint5 | L1: Sprint6 | M1: Sprint7 | N1: Sprint8 | O1: Sprint9 | P1: Sprint10 | Q1: Sprint11 | R1: Etiquetas | S1: Etiquetas10 | T1: Etiquetas11 | U1: Etiquetas12 | V1: Etiquetas13 | W1: Etiquetas14 | X1: Etiquetas15 | Y1: Etiquetas16 | Z1: Etiquetas17 | AA1: Informador | AB1: Creada | AC1: Versiones corregidas | AD1: Versiones corregidas19 | AE1: Versiones corregidas20 | AF1: Versiones corregidas21 | AG1: Módulo | AH1: Desarrollador | AI1: Desarrollador_Bug_Cancelado | AJ1: ¿En que Sprint fue encontrado? | AK1: ¿En qué versión fue encontrado? | AL1: ¿En qué versión fue corregido? | AM1: ¿En que Sprint fue corregido? | AN1: Categoría | AO1: Funcionalidad | AP1: Fue encontrado durante UAT? | AQ1: En que versión de UAT fue encontrado? | AR1: Fue devuelto? | AS1: Cuántas veces fue devuelto?
A2: Error | B2: T20-3755 | C2: 124509 | D2: POS - En menú BBB la opción “Abrir cajón” se muestra sin tilde | E2: Baja | F2: Tareas por hacer | R2: Controlar-Gaveta | S2: Look&Feel | T2: QA-IntegraciónV0.15 | AA2: Yubisleinys Mora Vega | AB2: 46024.531 | AG2: POS | AH2: Andres Vergara | AJ2: {=IFERROR(_xlfn.XLOOKUP(TRUE,COUNTIF(Tabla[[#This Row],[Etiquetas]:[Etiquetas17]],Versiones!$G$2:$G$36)>0,Versiones!$B$2:$B$36), "")} -> 25 | AK2: {=IFERROR(_xlfn.XLOOKUP(TRUE,COUNTIF(Tabla[[#This Row],[Etiquetas]:[Etiquetas17]],Versiones!$G$2:$G$36)>0,Versiones!$A$2:$A$36), "")} -> V0.15 | AL2: ="V"&MAX(IFERROR(VALUE(MID(Tabla[[#This Row],[Versiones corregidas]],2,99)),0), IFERROR(VALUE(MID(Tabla[[#This Row],[Versiones corregidas19]],2,99)),0), IFERROR(VALUE(MID(Tabla[[#This Row],[Versiones corregidas20]],2,99)),0), IFERROR(VALUE(MID(Tabla[[#This Row],[Versiones corregidas21]],2,99)),0),IFERROR(VALUE(MID(#REF!,2,99)),0)) -> V0 | AM2: =IFERROR(_xlfn.XLOOKUP(Tabla[[#This Row],[¿En qué versión fue corregido?]],Versiones!$A$2:$A$34,Versiones!$B$2:$B$34),"No encontrado") -> No encontrado | AN2: {=IFERROR(_xlfn.XLOOKUP(TRUE,COUNTIF(Tabla[[#This Row],[Etiquetas]:[Etiquetas17]],Categorías!$A$2:$A$12)>0,Categorías!$A$2:$A$12),"No encontrado")} -> Look&Feel | AO2: {=IFERROR(INDEX(Funcionalidades!$A$2:$A$80,MATCH(TRUE, COUNTIF(Reporte_Gral!R2:Z2,Funcionalidades!$A$2:$A$80)>0,0)),"No encontrado")} -> Controlar-Gaveta | AP2: =IF(AND(COUNTIF(Tabla[[#This Row],[Etiquetas]:[Etiquetas17]],"*UAT_V*")>0,COUNTIF(Tabla[[#This Row],[Etiquetas]:[Etiquetas17]],"*QA-Integración*")=0),"SI","") | AQ2: {=IF(Tabla[[#This Row],[Fue encontrado durante UAT?]]="SI",IFERROR(_xlfn.XLOOKUP(TRUE,ISNUMBER(SEARCH("UAT_V",Tabla[[#This Row],[Etiquetas]:[Etiquetas17]])),Tabla[[#This Row],[Etiquetas]:[Etiquetas17]]),""),"")} | AR2: =IF(COUNTIF(Tabla[[#This Row],[Etiquetas]:[Etiquetas17]],"*Devuelto*")>0,"SI","") | AS2: =COUNTIF(Tabla[[#This Row],[Etiquetas]:[Etiquetas17]],"*Devuelto*") -> 0
A3: Error | B3: T20-3752 | C3: 124120 | D3: POS – Realizar una venta crea copias del producto en el tablero y provoca cálculo incorrecto en unidades vendidas en el panel Ventas | E3: Alta | F3: Tareas por hacer | R3: Funcional | S3: Iniciar-Venta | T3: QA-IntegraciónV0.15 | AA3: Yubisleinys Mora Vega | AB3: 46021.659 | AG3: BOT | AH3: Ludovic Hern | AJ3: {=IFERROR(_xlfn.XLOOKUP(TRUE,COUNTIF(Tabla[[#This Row],[Etiquetas]:[Etiquetas17]],Versiones!$G$2:$G$36)>0,Versiones!$B$2:$B$36), "")} -> 25 | AK3: {=IFERROR(_xlfn.XLOOKUP(TRUE,COUNTIF(Tabla[[#This Row],[Etiquetas]:[Etiquetas17]],Versiones!$G$2:$G$36)>0,Versiones!$A$2:$A$36), "")} -> V0.15 | AL3: ="V"&MAX(IFERROR(VALUE(MID(Tabla[[#This Row],[Versiones corregidas]],2,99)),0), IFERROR(VALUE(MID(Tabla[[#This Row],[Versiones corregidas19]],2,99)),0), IFERROR(VALUE(MID(Tabla[[#This Row],[Versiones corregidas20]],2,99)),0), IFERROR(VALUE(MID(Tabla[[#This Row],[Versiones corregidas21]],2,99)),0),IFERROR(VALUE(MID(#REF!,2,99)),0)) -> V0 | AM3: =IFERROR(_xlfn.XLOOKUP(Tabla[[#This Row],[¿En qué versión fue corregido?]],Versiones!$A$2:$A$34,Versiones!$B$2:$B$34),"No encontrado") -> No encontrado | AN3: {=IFERROR(_xlfn.XLOOKUP(TRUE,COUNTIF(Tabla[[#This Row],[Etiquetas]:[Etiquetas17]],Categorías!$A$2:$A$12)>0,Categorías!$A$2:$A$12),"No encontrado")} -> Funcional | AO3: {=IFERROR(INDEX(Funcionalidades!$A$2:$A$80,MATCH(TRUE, COUNTIF(Reporte_Gral!R3:Z3,Funcionalidades!$A$2:$A$80)>0,0)),"No encontrado")} -> Iniciar-Venta | AP3: =IF(AND(COUNTIF(Tabla[[#This Row],[Etiquetas]:[Etiquetas17]],"*UAT_V*")>0,COUNTIF(Tabla[[#This Row],[Etiquetas]:[Etiquetas17]],"*QA-Integración*")=0),"SI","") | AQ3: {=IF(Tabla[[#This Row],[Fue encontrado durante UAT?]]="SI",IFERROR(_xlfn.XLOOKUP(TRUE,ISNUMBER(SEARCH("UAT_V",Tabla[[#This Row],[Etiquetas]:[Etiquetas17]])),Tabla[[#This Row],[Etiquetas]:[Etiquetas17]]),""),"")} | AR3: =IF(COUNTIF(Tabla[[#This Row],[Etiquetas]:[Etiquetas17]],"*Devuelto*")>0,"SI","") | AS3: =COUNTIF(Tabla[[#This Row],[Etiquetas]:[Etiquetas17]],"*Devuelto*") -> 0
A4: Error | B4: T20-3751 | C4: 124095 | D4: POS - Se genera mensaje de alivio independiente y el cierre de turno muestra importes incorrectos | E4: Alta | F4: Tareas por hacer | R4: Cierre-De-Turno | S4: Funcional | T4: QA-IntegraciónV0.15 | AA4: Yubisleinys Mora Vega | AB4: 46021.608 | AG4: BOT | AH4: Ludovic Hern | AJ4: {=IFERROR(_xlfn.XLOOKUP(TRUE,COUNTIF(Tabla[[#This Row],[Etiquetas]:[Etiquetas17]],Versiones!$G$2:$G$36)>0,Versiones!$B$2:$B$36), "")} -> 25 | AK4: {=IFERROR(_xlfn.XLOOKUP(TRUE,COUNTIF(Tabla[[#This Row],[Etiquetas]:[Etiquetas17]],Versiones!$G$2:$G$36)>0,Versiones!$A$2:$A$36), "")} -> V0.15 | AL4: ="V"&MAX(IFERROR(VALUE(MID(Tabla[[#This Row],[Versiones corregidas]],2,99)),0), IFERROR(VALUE(MID(Tabla[[#This Row],[Versiones corregidas19]],2,99)),0), IFERROR(VALUE(MID(Tabla[[#This Row],[Versiones corregidas20]],2,99)),0), IFERROR(VALUE(MID(Tabla[[#This Row],[Versiones corregidas21]],2,99)),0),IFERROR(VALUE(MID(#REF!,2,99)),0)) -> V0 | AM4: =IFERROR(_xlfn.XLOOKUP(Tabla[[#This Row],[¿En qué versión fue corregido?]],Versiones!$A$2:$A$34,Versiones!$B$2:$B$34),"No encontrado") -> No encontrado | AN4: {=IFERROR(_xlfn.XLOOKUP(TRUE,COUNTIF(Tabla[[#This Row],[Etiquetas]:[Etiquetas17]],Categorías!$A$2:$A$12)>0,Categorías!$A$2:$A$12),"No encontrado")} -> Funcional | AO4: {=IFERROR(INDEX(Funcionalidades!$A$2:$A$80,MATCH(TRUE, COUNTIF(Reporte_Gral!R4:Z4,Funcionalidades!$A$2:$A$80)>0,0)),"No encontrado")} -> Cierre-De-Turno | AP4: =IF(AND(COUNTIF(Tabla[[#This Row],[Etiquetas]:[Etiquetas17]],"*UAT_V*")>0,COUNTIF(Tabla[[#This Row],[Etiquetas]:[Etiquetas17]],"*QA-Integración*")=0),"SI","") | AQ4: {=IF(Tabla[[#This Row],[Fue encontrado durante UAT?]]="SI",IFERROR(_xlfn.XLOOKUP(TRUE,ISNUMBER(SEARCH("UAT_V",Tabla[[#This Row],[Etiquetas]:[Etiquetas17]])),Tabla[[#This Row],[Etiquetas]:[Etiquetas17]]),""),"")} | AR4: =IF(COUNTIF(Tabla[[#This Row],[Etiquetas]:[Etiquetas17]],"*Devuelto*")>0,"SI","") | AS4: =COUNTIF(Tabla[[#This Row],[Etiquetas]:[Etiquetas17]],"*Devuelto*") -> 0
A5: Error | B5: T20-3749 | C5: 124062 | D5: BOT – Al aceptar mensaje entrante de “Recibir Mercancía” con productos de la misma clave, se cierra el BOT y el mensaje queda en el tablero | E5: Alta | F5: Tareas por hacer | R5: Funcional | S5: QA-IntegraciónV0.15 | T5: Recibir-Mercancía-Almacén-Tienda | AA5: Yubisleinys Mora Vega | AB5: 46021.535 | AG5: BOT | AH5: Ludovic Hern | AJ5: {=IFERROR(_xlfn.XLOOKUP(TRUE,COUNTIF(Tabla[[#This Row],[Etiquetas]:[Etiquetas17]],Versiones!$G$2:$G$36)>0,Versiones!$B$2:$B$36), "")} -> 25 | AK5: {=IFERROR(_xlfn.XLOOKUP(TRUE,COUNTIF(Tabla[[#This Row],[Etiquetas]:[Etiquetas17]],Versiones!$G$2:$G$36)>0,Versiones!$A$2:$A$36), "")} -> V0.15 | AL5: ="V"&MAX(IFERROR(VALUE(MID(Tabla[[#This Row],[Versiones corregidas]],2,99)),0), IFERROR(VALUE(MID(Tabla[[#This Row],[Versiones corregidas19]],2,99)),0), IFERROR(VALUE(MID(Tabla[[#This Row],[Versiones corregidas20]],2,99)),0), IFERROR(VALUE(MID(Tabla[[#This Row],[Versiones corregidas21]],2,99)),0),IFERROR(VALUE(MID(#REF!,2,99)),0)) -> V0 | AM5: =IFERROR(_xlfn.XLOOKUP(Tabla[[#This Row],[¿En qué versión fue corregido?]],Versiones!$A$2:$A$34,Versiones!$B$2:$B$34),"No encontrado") -> No encontrado | AN5: {=IFERROR(_xlfn.XLOOKUP(TRUE,COUNTIF(Tabla[[#This Row],[Etiquetas]:[Etiquetas17]],Categorías!$A$2:$A$12)>0,Categorías!$A$2:$A$12),"No encontrado")} -> Funcional | AO5: {=IFERROR(INDEX(Funcionalidades!$A$2:$A$80,MATCH(TRUE, COUNTIF(Reporte_Gral!R5:Z5,Funcionalidades!$A$2:$A$80)>0,0)),"No encontrado")} -> Recibir-Mercancía-Almacén-Tienda | AP5: =IF(AND(COUNTIF(Tabla[[#This Row],[Etiquetas]:[Etiquetas17]],"*UAT_V*")>0,COUNTIF(Tabla[[#This Row],[Etiquetas]:[Etiquetas17]],"*QA-Integración*")=0),"SI","") | AQ5: {=IF(Tabla[[#This Row],[Fue encontrado durante UAT?]]="SI",IFERROR(_xlfn.XLOOKUP(TRUE,ISNUMBER(SEARCH("UAT_V",Tabla[[#This Row],[Etiquetas]:[Etiquetas17]])),Tabla[[#This Row],[Etiquetas]:[Etiquetas17]]),""),"")} | AR5: =IF(COUNTIF(Tabla[[#This Row],[Etiquetas]:[Etiquetas17]],"*Devuelto*")>0,"SI","") | AS5: =COUNTIF(Tabla[[#This Row],[Etiquetas]:[Etiquetas17]],"*Devuelto*") -> 0
A6: Error | B6: T20-3746 | C6: 123840 | D6: BOT - Impresora de carátula no imprime | E6: Alta | F6: TO BE DEPLOYED-SIT | G6: T20 Sprint 26 2025 | R6: Funcional | S6: QA-IntegraciónV0.15 | T6: Registrar-Merma | U6: T3B20_Kotlin | V6: Tienda2.0 | AA6: Yubisleinys Mora Vega | AB6: 46020.558 | AC6: v0.16 | AG6: BOT | AH6: Ludovic Hern | AJ6: {=IFERROR(_xlfn.XLOOKUP(TRUE,COUNTIF(Tabla[[#This Row],[Etiquetas]:[Etiquetas17]],Versiones!$G$2:$G$36)>0,Versiones!$B$2:$B$36), "")} -> 25 | AK6: {=IFERROR(_xlfn.XLOOKUP(TRUE,COUNTIF(Tabla[[#This Row],[Etiquetas]:[Etiquetas17]],Versiones!$G$2:$G$36)>0,Versiones!$A$2:$A$36), "")} -> V0.15 | AL6: ="V"&MAX(IFERROR(VALUE(MID(Tabla[[#This Row],[Versiones corregidas]],2,99)),0), IFERROR(VALUE(MID(Tabla[[#This Row],[Versiones corregidas19]],2,99)),0), IFERROR(VALUE(MID(Tabla[[#This Row],[Versiones corregidas20]],2,99)),0), IFERROR(VALUE(MID(Tabla[[#This Row],[Versiones corregidas21]],2,99)),0),IFERROR(VALUE(MID(#REF!,2,99)),0)) -> V0.16 | AM6: =IFERROR(_xlfn.XLOOKUP(Tabla[[#This Row],[¿En qué versión fue corregido?]],Versiones!$A$2:$A$34,Versiones!$B$2:$B$34),"No encontrado") -> 0 | AN6: {=IFERROR(_xlfn.XLOOKUP(TRUE,COUNTIF(Tabla[[#This Row],[Etiquetas]:[Etiquetas17]],Categorías!$A$2:$A$12)>0,Categorías!$A$2:$A$12),"No encontrado")} -> Funcional | AO6: {=IFERROR(INDEX(Funcionalidades!$A$2:$A$80,MATCH(TRUE, COUNTIF(Reporte_Gral!R6:Z6,Funcionalidades!$A$2:$A$80)>0,0)),"No encontrado")} -> Registrar-Merma | AP6: =IF(AND(COUNTIF(Tabla[[#This Row],[Etiquetas]:[Etiquetas17]],"*UAT_V*")>0,COUNTIF(Tabla[[#This Row],[Etiquetas]:[Etiquetas17]],"*QA-Integración*")=0),"SI","") | AQ6: {=IF(Tabla[[#This Row],[Fue encontrado durante UAT?]]="SI",IFERROR(_xlfn.XLOOKUP(TRUE,ISNUMBER(SEARCH("UAT_V",Tabla[[#This Row],[Etiquetas]:[Etiquetas17]])),Tabla[[#This Row],[Etiquetas]:[Etiquetas17]]),""),"")} | AR6: =IF(COUNTIF(Tabla[[#This Row],[Etiquetas]:[Etiquetas17]],"*Devuelto*")>0,"SI","") | AS6: =COUNTIF(Tabla[[#This Row],[Etiquetas]:[Etiquetas17]],"*Devuelto*") -> 0
A7: Error | B7: T20-3742 | C7: 123791 | D7: POS - Alivio - Espacio en blanco adicional en tickets de alivio | E7: Baja | F7: Tareas por hacer | R7: Alivios | S7: Funcional | T7: QA-IntegraciónV0.15 | AA7: Yubisleinys Mora Vega | AB7: 46020.446 | AG7: POS | AH7: Juan Munoz | AJ7: {=IFERROR(_xlfn.XLOOKUP(TRUE,COUNTIF(Tabla[[#This Row],[Etiquetas]:[Etiquetas17]],Versiones!$G$2:$G$36)>0,Versiones!$B$2:$B$36), "")} -> 25 | AK7: {=IFERROR(_xlfn.XLOOKUP(TRUE,COUNTIF(Tabla[[#This Row],[Etiquetas]:[Etiquetas17]],Versiones!$G$2:$G$36)>0,Versiones!$A$2:$A$36), "")} -> V0.15 | AL7: ="V"&MAX(IFERROR(VALUE(MID(Tabla[[#This Row],[Versiones corregidas]],2,99)),0), IFERROR(VALUE(MID(Tabla[[#This Row],[Versiones corregidas19]],2,99)),0), IFERROR(VALUE(MID(Tabla[[#This Row],[Versiones corregidas20]],2,99)),0), IFERROR(VALUE(MID(Tabla[[#This Row],[Versiones corregidas21]],2,99)),0),IFERROR(VALUE(MID(#REF!,2,99)),0)) -> V0 | AM7: =IFERROR(_xlfn.XLOOKUP(Tabla[[#This Row],[¿En qué versión fue corregido?]],Versiones!$A$2:$A$34,Versiones!$B$2:$B$34),"No encontrado") -> No encontrado | AN7: {=IFERROR(_xlfn.XLOOKUP(TRUE,COUNTIF(Tabla[[#This Row],[Etiquetas]:[Etiquetas17]],Categorías!$A$2:$A$12)>0,Categorías!$A$2:$A$12),"No encontrado")} -> Funcional | AO7: {=IFERROR(INDEX(Funcionalidades!$A$2:$A$80,MATCH(TRUE, COUNTIF(Reporte_Gral!R7:Z7,Funcionalidades!$A$2:$A$80)>0,0)),"No encontrado")} -> Alivios | AP7: =IF(AND(COUNTIF(Tabla[[#This Row],[Etiquetas]:[Etiquetas17]],"*UAT_V*")>0,COUNTIF(Tabla[[#This Row],[Etiquetas]:[Etiquetas17]],"*QA-Integración*")=0),"SI","") | AQ7: {=IF(Tabla[[#This Row],[Fue encontrado durante UAT?]]="SI",IFERROR(_xlfn.XLOOKUP(TRUE,ISNUMBER(SEARCH("UAT_V",Tabla[[#This Row],[Etiquetas]:[Etiquetas17]])),Tabla[[#This Row],[Etiquetas]:[Etiquetas17]]),""),"")} | AR7: =IF(COUNTIF(Tabla[[#This Row],[Etiquetas]:[Etiquetas17]],"*Devuelto*")>0,"SI","") | AS7: =COUNTIF(Tabla[[#This Row],[Etiquetas]:[Etiquetas17]],"*Devuelto*") -> 0
A8: Error | B8: T20-3741 | C8: 123774 | D8: BOT - Cambio de precio - Error al guardar configuración de producto obliga al cierre del BOT (intermitente) | E8: Alta | F8: Tareas por hacer | R8: Funcional | S8: Imprimir-Cambios-De-Precio | T8: QA-IntegraciónV0.15 | AA8: Yubisleinys Mora Vega | AB8: 46020.408 | AG8: BOT | AH8: PENDIENTES | AJ8: {=IFERROR(_xlfn.XLOOKUP(TRUE,COUNTIF(Tabla[[#This Row],[Etiquetas]:[Etiquetas17]],Versiones!$G$2:$G$36)>0,Versiones!$B$2:$B$36), "")} -> 25 | AK8: {=IFERROR(_xlfn.XLOOKUP(TRUE,COUNTIF(Tabla[[#This Row],[Etiquetas]:[Etiquetas17]],Versiones!$G$2:$G$36)>0,Versiones!$A$2:$A$36), "")} -> V0.15 | AL8: ="V"&MAX(IFERROR(VALUE(MID(Tabla[[#This Row],[Versiones corregidas]],2,99)),0), IFERROR(VALUE(MID(Tabla[[#This Row],[Versiones corregidas19]],2,99)),0), IFERROR(VALUE(MID(Tabla[[#This Row],[Versiones corregidas20]],2,99)),0), IFERROR(VALUE(MID(Tabla[[#This Row],[Versiones corregidas21]],2,99)),0),IFERROR(VALUE(MID(#REF!,2,99)),0)) -> V0 | AM8: =IFERROR(_xlfn.XLOOKUP(Tabla[[#This Row],[¿En qué versión fue corregido?]],Versiones!$A$2:$A$34,Versiones!$B$2:$B$34),"No encontrado") -> No encontrado | AN8: {=IFERROR(_xlfn.XLOOKUP(TRUE,COUNTIF(Tabla[[#This Row],[Etiquetas]:[Etiquetas17]],Categorías!$A$2:$A$12)>0,Categorías!$A$2:$A$12),"No encontrado")} -> Funcional | AO8: {=IFERROR(INDEX(Funcionalidades!$A$2:$A$80,MATCH(TRUE, COUNTIF(Reporte_Gral!R8:Z8,Funcionalidades!$A$2:$A$80)>0,0)),"No encontrado")} -> Imprimir-Cambios-De-Precio | AP8: =IF(AND(COUNTIF(Tabla[[#This Row],[Etiquetas]:[Etiquetas17]],"*UAT_V*")>0,COUNTIF(Tabla[[#This Row],[Etiquetas]:[Etiquetas17]],"*QA-Integración*")=0),"SI","") | AQ8: {=IF(Tabla[[#This Row],[Fue encontrado durante UAT?]]="SI",IFERROR(_xlfn.XLOOKUP(TRUE,ISNUMBER(SEARCH("UAT_V",Tabla[[#This Row],[Etiquetas]:[Etiquetas17]])),Tabla[[#This Row],[Etiquetas]:[Etiquetas17]]),""),"")} | AR8: =IF(COUNTIF(Tabla[[#This Row],[Etiquetas]:[Etiquetas17]],"*Devuelto*")>0,"SI","") | AS8: =COUNTIF(Tabla[[#This Row],[Etiquetas]:[Etiquetas17]],"*Devuelto*") -> 0
A9: Error | B9: T20-3739 | C9: 123727 | D9: POS - Alivio automático para Tómbola imprime solo un ticket | E9: Medio | F9: Tareas por hacer | R9: Alivios | S9: Funcional | T9: QA-IntegraciónV0.15 | AA9: Yubisleinys Mora Vega | AB9: 46020.265 | AG9: POS | AH9: Juan Munoz | AJ9: {=IFERROR(_xlfn.XLOOKUP(TRUE,COUNTIF(Tabla[[#This Row],[Etiquetas]:[Etiquetas17]],Versiones!$G$2:$G$36)>0,Versiones!$B$2:$B$36), "")} -> 25 | AK9: {=IFERROR(_xlfn.XLOOKUP(TRUE,COUNTIF(Tabla[[#This Row],[Etiquetas]:[Etiquetas17]],Versiones!$G$2:$G$36)>0,Versiones!$A$2:$A$36), "")} -> V0.15 | AL9: ="V"&MAX(IFERROR(VALUE(MID(Tabla[[#This Row],[Versiones corregidas]],2,99)),0), IFERROR(VALUE(MID(Tabla[[#This Row],[Versiones corregidas19]],2,99)),0), IFERROR(VALUE(MID(Tabla[[#This Row],[Versiones corregidas20]],2,99)),0), IFERROR(VALUE(MID(Tabla[[#This Row],[Versiones corregidas21]],2,99)),0),IFERROR(VALUE(MID(#REF!,2,99)),0)) -> V0 | AM9: =IFERROR(_xlfn.XLOOKUP(Tabla[[#This Row],[¿En qué versión fue corregido?]],Versiones!$A$2:$A$34,Versiones!$B$2:$B$34),"No encontrado") -> No encontrado | AN9: {=IFERROR(_xlfn.XLOOKUP(TRUE,COUNTIF(Tabla[[#This Row],[Etiquetas]:[Etiquetas17]],Categorías!$A$2:$A$12)>0,Categorías!$A$2:$A$12),"No encontrado")} -> Funcional | AO9: {=IFERROR(INDEX(Funcionalidades!$A$2:$A$80,MATCH(TRUE, COUNTIF(Reporte_Gral!R9:Z9,Funcionalidades!$A$2:$A$80)>0,0)),"No encontrado")} -> Alivios | AP9: =IF(AND(COUNTIF(Tabla[[#This Row],[Etiquetas]:[Etiquetas17]],"*UAT_V*")>0,COUNTIF(Tabla[[#This Row],[Etiquetas]:[Etiquetas17]],"*QA-Integración*")=0),"SI","") | AQ9: {=IF(Tabla[[#This Row],[Fue encontrado durante UAT?]]="SI",IFERROR(_xlfn.XLOOKUP(TRUE,ISNUMBER(SEARCH("UAT_V",Tabla[[#This Row],[Etiquetas]:[Etiquetas17]])),Tabla[[#This Row],[Etiquetas]:[Etiquetas17]]),""),"")} | AR9: =IF(COUNTIF(Tabla[[#This Row],[Etiquetas]:[Etiquetas17]],"*Devuelto*")>0,"SI","") | AS9: =COUNTIF(Tabla[[#This Row],[Etiquetas]:[Etiquetas17]],"*Devuelto*") -> 0
A10: Error | B10: T20-3738 | C10: 123559 | D10: POS - Ticket de Tiempo de Aire no muestra el cambio al cliente | E10: Medio | F10: Tareas por hacer | R10: Funcional | S10: Pago-De-Tiempo-Aire | T10: QA-IntegraciónV0.15 | AA10: Yubisleinys Mora Vega | AB10: 46017.685 | AG10: POS | AH10: PENDIENTES | AJ10: {=IFERROR(_xlfn.XLOOKUP(TRUE,COUNTIF(Tabla[[#This Row],[Etiquetas]:[Etiquetas17]],Versiones!$G$2:$G$36)>0,Versiones!$B$2:$B$36), "")} -> 25 | AK10: {=IFERROR(_xlfn.XLOOKUP(TRUE,COUNTIF(Tabla[[#This Row],[Etiquetas]:[Etiquetas17]],Versiones!$G$2:$G$36)>0,Versiones!$A$2:$A$36), "")} -> V0.15 | AL10: ="V"&MAX(IFERROR(VALUE(MID(Tabla[[#This Row],[Versiones corregidas]],2,99)),0), IFERROR(VALUE(MID(Tabla[[#This Row],[Versiones corregidas19]],2,99)),0), IFERROR(VALUE(MID(Tabla[[#This Row],[Versiones corregidas20]],2,99)),0), IFERROR(VALUE(MID(Tabla[[#This Row],[Versiones corregidas21]],2,99)),0),IFERROR(VALUE(MID(#REF!,2,99)),0)) -> V0 | AM10: =IFERROR(_xlfn.XLOOKUP(Tabla[[#This Row],[¿En qué versión fue corregido?]],Versiones!$A$2:$A$34,Versiones!$B$2:$B$34),"No encontrado") -> No encontrado | AN10: {=IFERROR(_xlfn.XLOOKUP(TRUE,COUNTIF(Tabla[[#This Row],[Etiquetas]:[Etiquetas17]],Categorías!$A$2:$A$12)>0,Categorías!$A$2:$A$12),"No encontrado")} -> Funcional | AO10: {=IFERROR(INDEX(Funcionalidades!$A$2:$A$80,MATCH(TRUE, COUNTIF(Reporte_Gral!R10:Z10,Funcionalidades!$A$2:$A$80)>0,0)),"No encontrado")} -> Pago-De-Tiempo-Aire | AP10: =IF(AND(COUNTIF(Tabla[[#This Row],[Etiquetas]:[Etiquetas17]],"*UAT_V*")>0,COUNTIF(Tabla[[#This Row],[Etiquetas]:[Etiquetas17]],"*QA-Integración*")=0),"SI","") | AQ10: {=IF(Tabla[[#This Row],[Fue encontrado durante UAT?]]="SI",IFERROR(_xlfn.XLOOKUP(TRUE,ISNUMBER(SEARCH("UAT_V",Tabla[[#This Row],[Etiquetas]:[Etiquetas17]])),Tabla[[#This Row],[Etiquetas]:[Etiquetas17]]),""),"")} | AR10: =IF(COUNTIF(Tabla[[#This Row],[Etiquetas]:[Etiquetas17]],"*Devuelto*")>0,"SI","") | AS10: =COUNTIF(Tabla[[#This Row],[Etiquetas]:[Etiquetas17]],"*Devuelto*") -> 0
A11: Error | B11: T20-3737 | C11: 123542 | D11: POS - Ticket de Alivio para Tómbola muestra concepto incorrecto en la impresión | E11: Medio | F11: Tareas por hacer | R11: Alivios | S11: Funcional | T11: QA-IntegraciónV0.15 | AA11: Yubisleinys Mora Vega | AB11: 46017.66 | AG11: POS | AH11: Juan Munoz | AJ11: {=IFERROR(_xlfn.XLOOKUP(TRUE,COUNTIF(Tabla[[#This Row],[Etiquetas]:[Etiquetas17]],Versiones!$G$2:$G$36)>0,Versiones!$B$2:$B$36), "")} -> 25 | AK11: {=IFERROR(_xlfn.XLOOKUP(TRUE,COUNTIF(Tabla[[#This Row],[Etiquetas]:[Etiquetas17]],Versiones!$G$2:$G$36)>0,Versiones!$A$2:$A$36), "")} -> V0.15 | AL11: ="V"&MAX(IFERROR(VALUE(MID(Tabla[[#This Row],[Versiones corregidas]],2,99)),0), IFERROR(VALUE(MID(Tabla[[#This Row],[Versiones corregidas19]],2,99)),0), IFERROR(VALUE(MID(Tabla[[#This Row],[Versiones corregidas20]],2,99)),0), IFERROR(VALUE(MID(Tabla[[#This Row],[Versiones corregidas21]],2,99)),0),IFERROR(VALUE(MID(#REF!,2,99)),0)) -> V0 | AM11: =IFERROR(_xlfn.XLOOKUP(Tabla[[#This Row],[¿En qué versión fue corregido?]],Versiones!$A$2:$A$34,Versiones!$B$2:$B$34),"No encontrado") -> No encontrado | AN11: {=IFERROR(_xlfn.XLOOKUP(TRUE,COUNTIF(Tabla[[#This Row],[Etiquetas]:[Etiquetas17]],Categorías!$A$2:$A$12)>0,Categorías!$A$2:$A$12),"No encontrado")} -> Funcional | AO11: {=IFERROR(INDEX(Funcionalidades!$A$2:$A$80,MATCH(TRUE, COUNTIF(Reporte_Gral!R11:Z11,Funcionalidades!$A$2:$A$80)>0,0)),"No encontrado")} -> Alivios | AP11: =IF(AND(COUNTIF(Tabla[[#This Row],[Etiquetas]:[Etiquetas17]],"*UAT_V*")>0,COUNTIF(Tabla[[#This Row],[Etiquetas]:[Etiquetas17]],"*QA-Integración*")=0),"SI","") | AQ11: {=IF(Tabla[[#This Row],[Fue encontrado durante UAT?]]="SI",IFERROR(_xlfn.XLOOKUP(TRUE,ISNUMBER(SEARCH("UAT_V",Tabla[[#This Row],[Etiquetas]:[Etiquetas17]])),Tabla[[#This Row],[Etiquetas]:[Etiquetas17]]),""),"")} | AR11: =IF(COUNTIF(Tabla[[#This Row],[Etiquetas]:[Etiquetas17]],"*Devuelto*")>0,"SI","") | AS11: =COUNTIF(Tabla[[#This Row],[Etiquetas]:[Etiquetas17]],"*Devuelto*") -> 0
A12: Error | B12: T20-3735 | C12: 123001 | D12: POS - Servicios - Error en modal Cambio al cliente | E12: Medio | F12: Tareas por hacer | R12: Funcional | S12: Pago-De-Servicios-Con-Catálogo | T12: QA-IntegraciónV0.15 | AA12: Yubisleinys Mora Vega | AB12: 46014.735 | AC12: v0.15 | AG12: POS | AH12: Andres Vergara | AJ12: {=IFERROR(_xlfn.XLOOKUP(TRUE,COUNTIF(Tabla[[#This Row],[Etiquetas]:[Etiquetas17]],Versiones!$G$2:$G$36)>0,Versiones!$B$2:$B$36), "")} -> 25 | AK12: {=IFERROR(_xlfn.XLOOKUP(TRUE,COUNTIF(Tabla[[#This Row],[Etiquetas]:[Etiquetas17]],Versiones!$G$2:$G$36)>0,Versiones!$A$2:$A$36), "")} -> V0.15 | AL12: ="V"&MAX(IFERROR(VALUE(MID(Tabla[[#This Row],[Versiones corregidas]],2,99)),0), IFERROR(VALUE(MID(Tabla[[#This Row],[Versiones corregidas19]],2,99)),0), IFERROR(VALUE(MID(Tabla[[#This Row],[Versiones corregidas20]],2,99)),0), IFERROR(VALUE(MID(Tabla[[#This Row],[Versiones corregidas21]],2,99)),0),IFERROR(VALUE(MID(#REF!,2,99)),0)) -> V0.15 | AM12: =IFERROR(_xlfn.XLOOKUP(Tabla[[#This Row],[¿En qué versión fue corregido?]],Versiones!$A$2:$A$34,Versiones!$B$2:$B$34),"No encontrado") -> 25 | AN12: {=IFERROR(_xlfn.XLOOKUP(TRUE,COUNTIF(Tabla[[#This Row],[Etiquetas]:[Etiquetas17]],Categorías!$A$2:$A$12)>0,Categorías!$A$2:$A$12),"No encontrado")} -> Funcional | AO12: {=IFERROR(INDEX(Funcionalidades!$A$2:$A$80,MATCH(TRUE, COUNTIF(Reporte_Gral!R12:Z12,Funcionalidades!$A$2:$A$80)>0,0)),"No encontrado")} -> Pago-De-Servicios-Con-Catálogo | AP12: =IF(AND(COUNTIF(Tabla[[#This Row],[Etiquetas]:[Etiquetas17]],"*UAT_V*")>0,COUNTIF(Tabla[[#This Row],[Etiquetas]:[Etiquetas17]],"*QA-Integración*")=0),"SI","") | AQ12: {=IF(Tabla[[#This Row],[Fue encontrado durante UAT?]]="SI",IFERROR(_xlfn.XLOOKUP(TRUE,ISNUMBER(SEARCH("UAT_V",Tabla[[#This Row],[Etiquetas]:[Etiquetas17]])),Tabla[[#This Row],[Etiquetas]:[Etiquetas17]]),""),"")} | AR12: =IF(COUNTIF(Tabla[[#This Row],[Etiquetas]:[Etiquetas17]],"*Devuelto*")>0,"SI","") | AS12: =COUNTIF(Tabla[[#This Row],[Etiquetas]:[Etiquetas17]],"*Devuelto*") -> 0
A13: Error | B13: T20-3734 | C13: 122963 | D13: POS - El sistema permite realizar un alivio por una cantidad mayor al efectivo disponible | E13: Medio | F13: Tareas por hacer | R13: Alivios | S13: Funcional | T13: UAT_V0.15 | AA13: Yubisleinys Mora Vega | AB13: 46014.659 | AG13: BOT | AH13: Juan Munoz | AJ13: {=IFERROR(_xlfn.XLOOKUP(TRUE,COUNTIF(Tabla[[#This Row],[Etiquetas]:[Etiquetas17]],Versiones!$G$2:$G$36)>0,Versiones!$B$2:$B$36), "")} -> 25 | AK13: {=IFERROR(_xlfn.XLOOKUP(TRUE,COUNTIF(Tabla[[#This Row],[Etiquetas]:[Etiquetas17]],Versiones!$G$2:$G$36)>0,Versiones!$A$2:$A$36), "")} -> V0.15 | AL13: ="V"&MAX(IFERROR(VALUE(MID(Tabla[[#This Row],[Versiones corregidas]],2,99)),0), IFERROR(VALUE(MID(Tabla[[#This Row],[Versiones corregidas19]],2,99)),0), IFERROR(VALUE(MID(Tabla[[#This Row],[Versiones corregidas20]],2,99)),0), IFERROR(VALUE(MID(Tabla[[#This Row],[Versiones corregidas21]],2,99)),0),IFERROR(VALUE(MID(#REF!,2,99)),0)) -> V0 | AM13: =IFERROR(_xlfn.XLOOKUP(Tabla[[#This Row],[¿En qué versión fue corregido?]],Versiones!$A$2:$A$34,Versiones!$B$2:$B$34),"No encontrado") -> No encontrado | AN13: {=IFERROR(_xlfn.XLOOKUP(TRUE,COUNTIF(Tabla[[#This Row],[Etiquetas]:[Etiquetas17]],Categorías!$A$2:$A$12)>0,Categorías!$A$2:$A$12),"No encontrado")} -> Funcional | AO13: {=IFERROR(INDEX(Funcionalidades!$A$2:$A$80,MATCH(TRUE, COUNTIF(Reporte_Gral!R13:Z13,Funcionalidades!$A$2:$A$80)>0,0)),"No encontrado")} -> Alivios | AP13: =IF(AND(COUNTIF(Tabla[[#This Row],[Etiquetas]:[Etiquetas17]],"*UAT_V*")>0,COUNTIF(Tabla[[#This Row],[Etiquetas]:[Etiquetas17]],"*QA-Integración*")=0),"SI","") -> SI | AQ13: {=IF(Tabla[[#This Row],[Fue encontrado durante UAT?]]="SI",IFERROR(_xlfn.XLOOKUP(TRUE,ISNUMBER(SEARCH("UAT_V",Tabla[[#This Row],[Etiquetas]:[Etiquetas17]])),Tabla[[#This Row],[Etiquetas]:[Etiquetas17]]),""),"")} -> UAT_V0.15 | AR13: =IF(COUNTIF(Tabla[[#This Row],[Etiquetas]:[Etiquetas17]],"*Devuelto*")>0,"SI","") | AS13: =COUNTIF(Tabla[[#This Row],[Etiquetas]:[Etiquetas17]],"*Devuelto*") -> 0
A14: Error | B14: T20-3733 | C14: 122956 | D14: BOT - Registro de merma - El sistema permite realizar merma sobre pagos de servicios y recargas | E14: Medio | F14: Tareas por hacer | R14: Funcional | S14: Registrar-Merma | T14: UAT_V0.15 | AA14: Yubisleinys Mora Vega | AB14: 46014.633 | AG14: BOT | AH14: PENDIENTES | AJ14: {=IFERROR(_xlfn.XLOOKUP(TRUE,COUNTIF(Tabla[[#This Row],[Etiquetas]:[Etiquetas17]],Versiones!$G$2:$G$36)>0,Versiones!$B$2:$B$36), "")} -> 25 | AK14: {=IFERROR(_xlfn.XLOOKUP(TRUE,COUNTIF(Tabla[[#This Row],[Etiquetas]:[Etiquetas17]],Versiones!$G$2:$G$36)>0,Versiones!$A$2:$A$36), "")} -> V0.15 | AL14: ="V"&MAX(IFERROR(VALUE(MID(Tabla[[#This Row],[Versiones corregidas]],2,99)),0), IFERROR(VALUE(MID(Tabla[[#This Row],[Versiones corregidas19]],2,99)),0), IFERROR(VALUE(MID(Tabla[[#This Row],[Versiones corregidas20]],2,99)),0), IFERROR(VALUE(MID(Tabla[[#This Row],[Versiones corregidas21]],2,99)),0),IFERROR(VALUE(MID(#REF!,2,99)),0)) -> V0 | AM14: =IFERROR(_xlfn.XLOOKUP(Tabla[[#This Row],[¿En qué versión fue corregido?]],Versiones!$A$2:$A$34,Versiones!$B$2:$B$34),"No encontrado") -> No encontrado | AN14: {=IFERROR(_xlfn.XLOOKUP(TRUE,COUNTIF(Tabla[[#This Row],[Etiquetas]:[Etiquetas17]],Categorías!$A$2:$A$12)>0,Categorías!$A$2:$A$12),"No encontrado")} -> Funcional | AO14: {=IFERROR(INDEX(Funcionalidades!$A$2:$A$80,MATCH(TRUE, COUNTIF(Reporte_Gral!R14:Z14,Funcionalidades!$A$2:$A$80)>0,0)),"No encontrado")} -> Registrar-Merma | AP14: =IF(AND(COUNTIF(Tabla[[#This Row],[Etiquetas]:[Etiquetas17]],"*UAT_V*")>0,COUNTIF(Tabla[[#This Row],[Etiquetas]:[Etiquetas17]],"*QA-Integración*")=0),"SI","") -> SI | AQ14: {=IF(Tabla[[#This Row],[Fue encontrado durante UAT?]]="SI",IFERROR(_xlfn.XLOOKUP(TRUE,ISNUMBER(SEARCH("UAT_V",Tabla[[#This Row],[Etiquetas]:[Etiquetas17]])),Tabla[[#This Row],[Etiquetas]:[Etiquetas17]]),""),"")} -> UAT_V0.15 | AR14: =IF(COUNTIF(Tabla[[#This Row],[Etiquetas]:[Etiquetas17]],"*Devuelto*")>0,"SI","") | AS14: =COUNTIF(Tabla[[#This Row],[Etiquetas]:[Etiquetas17]],"*Devuelto*") -> 0
A15: Error | B15: T20-3702 | C15: 122888 | D15: BOT - Pedido eficiente - El resumen del pedido muestra todos los productos en lugar de solo los solicitados | E15: Alta | F15: Tareas por hacer | R15: Funcional | S15: Realizar-Pedido-Eficiente | T15: UAT_V0.15 | AA15: Yubisleinys Mora Vega | AB15: 46014.594 | AG15: BOT | AH15: Andres Vergara | AJ15: {=IFERROR(_xlfn.XLOOKUP(TRUE,COUNTIF(Tabla[[#This Row],[Etiquetas]:[Etiquetas17]],Versiones!$G$2:$G$36)>0,Versiones!$B$2:$B$36), "")} -> 25 | AK15: {=IFERROR(_xlfn.XLOOKUP(TRUE,COUNTIF(Tabla[[#This Row],[Etiquetas]:[Etiquetas17]],Versiones!$G$2:$G$36)>0,Versiones!$A$2:$A$36), "")} -> V0.15 | AL15: ="V"&MAX(IFERROR(VALUE(MID(Tabla[[#This Row],[Versiones corregidas]],2,99)),0), IFERROR(VALUE(MID(Tabla[[#This Row],[Versiones corregidas19]],2,99)),0), IFERROR(VALUE(MID(Tabla[[#This Row],[Versiones corregidas20]],2,99)),0), IFERROR(VALUE(MID(Tabla[[#This Row],[Versiones corregidas21]],2,99)),0),IFERROR(VALUE(MID(#REF!,2,99)),0)) -> V0 | AM15: =IFERROR(_xlfn.XLOOKUP(Tabla[[#This Row],[¿En qué versión fue corregido?]],Versiones!$A$2:$A$34,Versiones!$B$2:$B$34),"No encontrado") -> No encontrado | AN15: {=IFERROR(_xlfn.XLOOKUP(TRUE,COUNTIF(Tabla[[#This Row],[Etiquetas]:[Etiquetas17]],Categorías!$A$2:$A$12)>0,Categorías!$A$2:$A$12),"No encontrado")} -> Funcional | AO15: {=IFERROR(INDEX(Funcionalidades!$A$2:$A$80,MATCH(TRUE, COUNTIF(Reporte_Gral!R15:Z15,Funcionalidades!$A$2:$A$80)>0,0)),"No encontrado")} -> Realizar-Pedido-Eficiente | AP15: =IF(AND(COUNTIF(Tabla[[#This Row],[Etiquetas]:[Etiquetas17]],"*UAT_V*")>0,COUNTIF(Tabla[[#This Row],[Etiquetas]:[Etiquetas17]],"*QA-Integración*")=0),"SI","") -> SI | AQ15: {=IF(Tabla[[#This Row],[Fue encontrado durante UAT?]]="SI",IFERROR(_xlfn.XLOOKUP(TRUE,ISNUMBER(SEARCH("UAT_V",Tabla[[#This Row],[Etiquetas]:[Etiquetas17]])),Tabla[[#This Row],[Etiquetas]:[Etiquetas17]]),""),"")} -> UAT_V0.15 | AR15: =IF(COUNTIF(Tabla[[#This Row],[Etiquetas]:[Etiquetas17]],"*Devuelto*")>0,"SI","") | AS15: =COUNTIF(Tabla[[#This Row],[Etiquetas]:[Etiquetas17]],"*Devuelto*") -> 0
A16: Error | B16: T20-3701 | C16: 122869 | D16: BOT - Cambio de precio - Es necesario realizar dos clics para que el tipo de señalización “Tachado” funcione correctamente | E16: Medio | F16: Tareas por hacer | R16: Funcional | S16: Imprimir-Cambios-De-Precio | T16: QA-IntegraciónV0.15 | AA16: Yubisleinys Mora Vega | AB16: 46014.553 | AG16: BOT | AH16: CANCELADO | AJ16: {=IFERROR(_xlfn.XLOOKUP(TRUE,COUNTIF(Tabla[[#This Row],[Etiquetas]:[Etiquetas17]],Versiones!$G$2:$G$36)>0,Versiones!$B$2:$B$36), "")} -> 25 | AK16: {=IFERROR(_xlfn.XLOOKUP(TRUE,COUNTIF(Tabla[[#This Row],[Etiquetas]:[Etiquetas17]],Versiones!$G$2:$G$36)>0,Versiones!$A$2:$A$36), "")} -> V0.15 | AL16: ="V"&MAX(IFERROR(VALUE(MID(Tabla[[#This Row],[Versiones corregidas]],2,99)),0), IFERROR(VALUE(MID(Tabla[[#This Row],[Versiones corregidas19]],2,99)),0), IFERROR(VALUE(MID(Tabla[[#This Row],[Versiones corregidas20]],2,99)),0), IFERROR(VALUE(MID(Tabla[[#This Row],[Versiones corregidas21]],2,99)),0),IFERROR(VALUE(MID(#REF!,2,99)),0)) -> V0 | AM16: =IFERROR(_xlfn.XLOOKUP(Tabla[[#This Row],[¿En qué versión fue corregido?]],Versiones!$A$2:$A$34,Versiones!$B$2:$B$34),"No encontrado") -> No encontrado | AN16: {=IFERROR(_xlfn.XLOOKUP(TRUE,COUNTIF(Tabla[[#This Row],[Etiquetas]:[Etiquetas17]],Categorías!$A$2:$A$12)>0,Categorías!$A$2:$A$12),"No encontrado")} -> Funcional | AO16: {=IFERROR(INDEX(Funcionalidades!$A$2:$A$80,MATCH(TRUE, COUNTIF(Reporte_Gral!R16:Z16,Funcionalidades!$A$2:$A$80)>0,0)),"No encontrado")} -> Imprimir-Cambios-De-Precio | AP16: =IF(AND(COUNTIF(Tabla[[#This Row],[Etiquetas]:[Etiquetas17]],"*UAT_V*")>0,COUNTIF(Tabla[[#This Row],[Etiquetas]:[Etiquetas17]],"*QA-Integración*")=0),"SI","") | AQ16: {=IF(Tabla[[#This Row],[Fue encontrado durante UAT?]]="SI",IFERROR(_xlfn.XLOOKUP(TRUE,ISNUMBER(SEARCH("UAT_V",Tabla[[#This Row],[Etiquetas]:[Etiquetas17]])),Tabla[[#This Row],[Etiquetas]:[Etiquetas17]]),""),"")} | AR16: =IF(COUNTIF(Tabla[[#This Row],[Etiquetas]:[Etiquetas17]],"*Devuelto*")>0,"SI","") | AS16: =COUNTIF(Tabla[[#This Row],[Etiquetas]:[Etiquetas17]],"*Devuelto*") -> 0
A17: Error | B17: T20-3692 | C17: 122677 | D17: POS - No existe tope al multiplicar cantidades, generando valores negativos | E17: Medio | F17: Tareas por hacer | R17: Funcional | S17: Multiplicar-Producto | T17: QA-IntegraciónV0.15 | U17: UAT | V17: UAT_V0.15 | AA17: Yubisleinys Mora Vega | AB17: 46013.712 | AG17: POS | AH17: PENDIENTES | AJ17: {=IFERROR(_xlfn.XLOOKUP(TRUE,COUNTIF(Tabla[[#This Row],[Etiquetas]:[Etiquetas17]],Versiones!$G$2:$G$36)>0,Versiones!$B$2:$B$36), "")} -> 25 | AK17: {=IFERROR(_xlfn.XLOOKUP(TRUE,COUNTIF(Tabla[[#This Row],[Etiquetas]:[Etiquetas17]],Versiones!$G$2:$G$36)>0,Versiones!$A$2:$A$36), "")} -> V0.15 | AL17: ="V"&MAX(IFERROR(VALUE(MID(Tabla[[#This Row],[Versiones corregidas]],2,99)),0), IFERROR(VALUE(MID(Tabla[[#This Row],[Versiones corregidas19]],2,99)),0), IFERROR(VALUE(MID(Tabla[[#This Row],[Versiones corregidas20]],2,99)),0), IFERROR(VALUE(MID(Tabla[[#This Row],[Versiones corregidas21]],2,99)),0),IFERROR(VALUE(MID(#REF!,2,99)),0)) -> V0 | AM17: =IFERROR(_xlfn.XLOOKUP(Tabla[[#This Row],[¿En qué versión fue corregido?]],Versiones!$A$2:$A$34,Versiones!$B$2:$B$34),"No encontrado") -> No encontrado | AN17: {=IFERROR(_xlfn.XLOOKUP(TRUE,COUNTIF(Tabla[[#This Row],[Etiquetas]:[Etiquetas17]],Categorías!$A$2:$A$12)>0,Categorías!$A$2:$A$12),"No encontrado")} -> Funcional | AO17: {=IFERROR(INDEX(Funcionalidades!$A$2:$A$80,MATCH(TRUE, COUNTIF(Reporte_Gral!R17:Z17,Funcionalidades!$A$2:$A$80)>0,0)),"No encontrado")} -> Multiplicar-Producto | AP17: =IF(AND(COUNTIF(Tabla[[#This Row],[Etiquetas]:[Etiquetas17]],"*UAT_V*")>0,COUNTIF(Tabla[[#This Row],[Etiquetas]:[Etiquetas17]],"*QA-Integración*")=0),"SI","") | AQ17: {=IF(Tabla[[#This Row],[Fue encontrado durante UAT?]]="SI",IFERROR(_xlfn.XLOOKUP(TRUE,ISNUMBER(SEARCH("UAT_V",Tabla[[#This Row],[Etiquetas]:[Etiquetas17]])),Tabla[[#This Row],[Etiquetas]:[Etiquetas17]]),""),"")} | AR17: =IF(COUNTIF(Tabla[[#This Row],[Etiquetas]:[Etiquetas17]],"*Devuelto*")>0,"SI","") | AS17: =COUNTIF(Tabla[[#This Row],[Etiquetas]:[Etiquetas17]],"*Devuelto*") -> 0
A18: Error | B18: T20-3691 | C18: 122602 | D18: BOT - Desaparición de números en alivios agregados | E18: Medio | F18: Tareas por hacer | R18: Entrega-de-Valores | S18: Funcional | T18: QA-IntegraciónV0.15 | U18: UAT | AA18: Yubisleinys Mora Vega | AB18: 46013.627 | AG18: BOT | AH18: Ludovic Hern | AJ18: {=IFERROR(_xlfn.XLOOKUP(TRUE,COUNTIF(Tabla[[#This Row],[Etiquetas]:[Etiquetas17]],Versiones!$G$2:$G$36)>0,Versiones!$B$2:$B$36), "")} -> 25 | AK18: {=IFERROR(_xlfn.XLOOKUP(TRUE,COUNTIF(Tabla[[#This Row],[Etiquetas]:[Etiquetas17]],Versiones!$G$2:$G$36)>0,Versiones!$A$2:$A$36), "")} -> V0.15 | AL18: ="V"&MAX(IFERROR(VALUE(MID(Tabla[[#This Row],[Versiones corregidas]],2,99)),0), IFERROR(VALUE(MID(Tabla[[#This Row],[Versiones corregidas19]],2,99)),0), IFERROR(VALUE(MID(Tabla[[#This Row],[Versiones corregidas20]],2,99)),0), IFERROR(VALUE(MID(Tabla[[#This Row],[Versiones corregidas21]],2,99)),0),IFERROR(VALUE(MID(#REF!,2,99)),0)) -> V0 | AM18: =IFERROR(_xlfn.XLOOKUP(Tabla[[#This Row],[¿En qué versión fue corregido?]],Versiones!$A$2:$A$34,Versiones!$B$2:$B$34),"No encontrado") -> No encontrado | AN18: {=IFERROR(_xlfn.XLOOKUP(TRUE,COUNTIF(Tabla[[#This Row],[Etiquetas]:[Etiquetas17]],Categorías!$A$2:$A$12)>0,Categorías!$A$2:$A$12),"No encontrado")} -> Funcional | AO18: {=IFERROR(INDEX(Funcionalidades!$A$2:$A$80,MATCH(TRUE, COUNTIF(Reporte_Gral!R18:Z18,Funcionalidades!$A$2:$A$80)>0,0)),"No encontrado")} -> Entrega-De-Valores | AP18: =IF(AND(COUNTIF(Tabla[[#This Row],[Etiquetas]:[Etiquetas17]],"*UAT_V*")>0,COUNTIF(Tabla[[#This Row],[Etiquetas]:[Etiquetas17]],"*QA-Integración*")=0),"SI","") | AQ18: {=IF(Tabla[[#This Row],[Fue encontrado durante UAT?]]="SI",IFERROR(_xlfn.XLOOKUP(TRUE,ISNUMBER(SEARCH("UAT_V",Tabla[[#This Row],[Etiquetas]:[Etiquetas17]])),Tabla[[#This Row],[Etiquetas]:[Etiquetas17]]),""),"")} | AR18: =IF(COUNTIF(Tabla[[#This Row],[Etiquetas]:[Etiquetas17]],"*Devuelto*")>0,"SI","") | AS18: =COUNTIF(Tabla[[#This Row],[Etiquetas]:[Etiquetas17]],"*Devuelto*") -> 0
A19: Error | B19: T20-3690 | C19: 122599 | D19: POS - Pago de Servicio - El último valor agregado no se elimina en el comprobante de servicio | E19: Medio | F19: Tareas por hacer | R19: Funcional | S19: Pago-De-Servicios-Con-Catálogo | T19: QA-IntegraciónV0.15 | U19: Revisado | V19: UAT | AA19: Yubisleinys Mora Vega | AB19: 46013.615 | AG19: POS | AH19: PENDIENTES | AJ19: {=IFERROR(_xlfn.XLOOKUP(TRUE,COUNTIF(Tabla[[#This Row],[Etiquetas]:[Etiquetas17]],Versiones!$G$2:$G$36)>0,Versiones!$B$2:$B$36), "")} -> 25 | AK19: {=IFERROR(_xlfn.XLOOKUP(TRUE,COUNTIF(Tabla[[#This Row],[Etiquetas]:[Etiquetas17]],Versiones!$G$2:$G$36)>0,Versiones!$A$2:$A$36), "")} -> V0.15 | AL19: ="V"&MAX(IFERROR(VALUE(MID(Tabla[[#This Row],[Versiones corregidas]],2,99)),0), IFERROR(VALUE(MID(Tabla[[#This Row],[Versiones corregidas19]],2,99)),0), IFERROR(VALUE(MID(Tabla[[#This Row],[Versiones corregidas20]],2,99)),0), IFERROR(VALUE(MID(Tabla[[#This Row],[Versiones corregidas21]],2,99)),0),IFERROR(VALUE(MID(#REF!,2,99)),0)) -> V0 | AM19: =IFERROR(_xlfn.XLOOKUP(Tabla[[#This Row],[¿En qué versión fue corregido?]],Versiones!$A$2:$A$34,Versiones!$B$2:$B$34),"No encontrado") -> No encontrado | AN19: {=IFERROR(_xlfn.XLOOKUP(TRUE,COUNTIF(Tabla[[#This Row],[Etiquetas]:[Etiquetas17]],Categorías!$A$2:$A$12)>0,Categorías!$A$2:$A$12),"No encontrado")} -> Funcional | AO19: {=IFERROR(INDEX(Funcionalidades!$A$2:$A$80,MATCH(TRUE, COUNTIF(Reporte_Gral!R19:Z19,Funcionalidades!$A$2:$A$80)>0,0)),"No encontrado")} -> Pago-De-Servicios-Con-Catálogo | AP19: =IF(AND(COUNTIF(Tabla[[#This Row],[Etiquetas]:[Etiquetas17]],"*UAT_V*")>0,COUNTIF(Tabla[[#This Row],[Etiquetas]:[Etiquetas17]],"*QA-Integración*")=0),"SI","") | AQ19: {=IF(Tabla[[#This Row],[Fue encontrado durante UAT?]]="SI",IFERROR(_xlfn.XLOOKUP(TRUE,ISNUMBER(SEARCH("UAT_V",Tabla[[#This Row],[Etiquetas]:[Etiquetas17]])),Tabla[[#This Row],[Etiquetas]:[Etiquetas17]]),""),"")} | AR19: =IF(COUNTIF(Tabla[[#This Row],[Etiquetas]:[Etiquetas17]],"*Devuelto*")>0,"SI","") | AS19: =COUNTIF(Tabla[[#This Row],[Etiquetas]:[Etiquetas17]],"*Devuelto*") -> 0
A20: Error | B20: T20-3685 | C20: 122555 | D20: POS - Ticket de cobro con CODI no muestra folio ni número de transacción | E20: Alta | F20: Tareas por hacer | R20: Funcional | S20: Pago-Codi | T20: QA-IntegraciónV0.15 | U20: Revisado | V20: UAT | AA20: Yubisleinys Mora Vega | AB20: 46013.521 | AG20: POS | AH20: PENDIENTES | AJ20: {=IFERROR(_xlfn.XLOOKUP(TRUE,COUNTIF(Tabla[[#This Row],[Etiquetas]:[Etiquetas17]],Versiones!$G$2:$G$36)>0,Versiones!$B$2:$B$36), "")} -> 25 | AK20: {=IFERROR(_xlfn.XLOOKUP(TRUE,COUNTIF(Tabla[[#This Row],[Etiquetas]:[Etiquetas17]],Versiones!$G$2:$G$36)>0,Versiones!$A$2:$A$36), "")} -> V0.15 | AL20: ="V"&MAX(IFERROR(VALUE(MID(Tabla[[#This Row],[Versiones corregidas]],2,99)),0), IFERROR(VALUE(MID(Tabla[[#This Row],[Versiones corregidas19]],2,99)),0), IFERROR(VALUE(MID(Tabla[[#This Row],[Versiones corregidas20]],2,99)),0), IFERROR(VALUE(MID(Tabla[[#This Row],[Versiones corregidas21]],2,99)),0),IFERROR(VALUE(MID(#REF!,2,99)),0)) -> V0 | AM20: =IFERROR(_xlfn.XLOOKUP(Tabla[[#This Row],[¿En qué versión fue corregido?]],Versiones!$A$2:$A$34,Versiones!$B$2:$B$34),"No encontrado") -> No encontrado | AN20: {=IFERROR(_xlfn.XLOOKUP(TRUE,COUNTIF(Tabla[[#This Row],[Etiquetas]:[Etiquetas17]],Categorías!$A$2:$A$12)>0,Categorías!$A$2:$A$12),"No encontrado")} -> Funcional | AO20: {=IFERROR(INDEX(Funcionalidades!$A$2:$A$80,MATCH(TRUE, COUNTIF(Reporte_Gral!R20:Z20,Funcionalidades!$A$2:$A$80)>0,0)),"No encontrado")} -> Pago-CODI | AP20: =IF(AND(COUNTIF(Tabla[[#This Row],[Etiquetas]:[Etiquetas17]],"*UAT_V*")>0,COUNTIF(Tabla[[#This Row],[Etiquetas]:[Etiquetas17]],"*QA-Integración*")=0),"SI","") | AQ20: {=IF(Tabla[[#This Row],[Fue encontrado durante UAT?]]="SI",IFERROR(_xlfn.XLOOKUP(TRUE,ISNUMBER(SEARCH("UAT_V",Tabla[[#This Row],[Etiquetas]:[Etiquetas17]])),Tabla[[#This Row],[Etiquetas]:[Etiquetas17]]),""),"")} | AR20: =IF(COUNTIF(Tabla[[#This Row],[Etiquetas]:[Etiquetas17]],"*Devuelto*")>0,"SI","") | AS20: =COUNTIF(Tabla[[#This Row],[Etiquetas]:[Etiquetas17]],"*Devuelto*") -> 0
A21: Error | B21: T20-3684 | C21: 122543 | D21: POS - Pago de Servicio - No funcionan los atajos de teclado para aceptar Pago de Servicios en el POS | E21: Medio | F21: Tareas por hacer | R21: Funcional | S21: Pago-De-Servicios-Con-Catálogo | T21: QA-IntegraciónV0.15 | U21: UAT | AA21: Yubisleinys Mora Vega | AB21: 46013.497 | AG21: POS | AH21: PENDIENTES | AJ21: {=IFERROR(_xlfn.XLOOKUP(TRUE,COUNTIF(Tabla[[#This Row],[Etiquetas]:[Etiquetas17]],Versiones!$G$2:$G$36)>0,Versiones!$B$2:$B$36), "")} -> 25 | AK21: {=IFERROR(_xlfn.XLOOKUP(TRUE,COUNTIF(Tabla[[#This Row],[Etiquetas]:[Etiquetas17]],Versiones!$G$2:$G$36)>0,Versiones!$A$2:$A$36), "")} -> V0.15 | AL21: ="V"&MAX(IFERROR(VALUE(MID(Tabla[[#This Row],[Versiones corregidas]],2,99)),0), IFERROR(VALUE(MID(Tabla[[#This Row],[Versiones corregidas19]],2,99)),0), IFERROR(VALUE(MID(Tabla[[#This Row],[Versiones corregidas20]],2,99)),0), IFERROR(VALUE(MID(Tabla[[#This Row],[Versiones corregidas21]],2,99)),0),IFERROR(VALUE(MID(#REF!,2,99)),0)) -> V0 | AM21: =IFERROR(_xlfn.XLOOKUP(Tabla[[#This Row],[¿En qué versión fue corregido?]],Versiones!$A$2:$A$34,Versiones!$B$2:$B$34),"No encontrado") -> No encontrado | AN21: {=IFERROR(_xlfn.XLOOKUP(TRUE,COUNTIF(Tabla[[#This Row],[Etiquetas]:[Etiquetas17]],Categorías!$A$2:$A$12)>0,Categorías!$A$2:$A$12),"No encontrado")} -> Funcional | AO21: {=IFERROR(INDEX(Funcionalidades!$A$2:$A$80,MATCH(TRUE, COUNTIF(Reporte_Gral!R21:Z21,Funcionalidades!$A$2:$A$80)>0,0)),"No encontrado")} -> Pago-De-Servicios-Con-Catálogo | AP21: =IF(AND(COUNTIF(Tabla[[#This Row],[Etiquetas]:[Etiquetas17]],"*UAT_V*")>0,COUNTIF(Tabla[[#This Row],[Etiquetas]:[Etiquetas17]],"*QA-Integración*")=0),"SI","") | AQ21: {=IF(Tabla[[#This Row],[Fue encontrado durante UAT?]]="SI",IFERROR(_xlfn.XLOOKUP(TRUE,ISNUMBER(SEARCH("UAT_V",Tabla[[#This Row],[Etiquetas]:[Etiquetas17]])),Tabla[[#This Row],[Etiquetas]:[Etiquetas17]]),""),"")} | AR21: =IF(COUNTIF(Tabla[[#This Row],[Etiquetas]:[Etiquetas17]],"*Devuelto*")>0,"SI","") | AS21: =COUNTIF(Tabla[[#This Row],[Etiquetas]:[Etiquetas17]],"*Devuelto*") -> 0
A22: Error | B22: T20-3683 | C22: 122534 | D22: POS - Pago de Servicio - No se visualiza el monto de la comisión en el ticket | E22: Medio | F22: Tareas por hacer | R22: Funcional | S22: Pago-De-Servicios-Con-Catálogo | T22: QA-IntegraciónV0.15 | U22: Revisado | V22: UAT | AA22: Yubisleinys Mora Vega | AB22: 46013.487 | AG22: POS | AH22: PENDIENTES | AJ22: {=IFERROR(_xlfn.XLOOKUP(TRUE,COUNTIF(Tabla[[#This Row],[Etiquetas]:[Etiquetas17]],Versiones!$G$2:$G$36)>0,Versiones!$B$2:$B$36), "")} -> 25 | AK22: {=IFERROR(_xlfn.XLOOKUP(TRUE,COUNTIF(Tabla[[#This Row],[Etiquetas]:[Etiquetas17]],Versiones!$G$2:$G$36)>0,Versiones!$A$2:$A$36), "")} -> V0.15 | AL22: ="V"&MAX(IFERROR(VALUE(MID(Tabla[[#This Row],[Versiones corregidas]],2,99)),0), IFERROR(VALUE(MID(Tabla[[#This Row],[Versiones corregidas19]],2,99)),0), IFERROR(VALUE(MID(Tabla[[#This Row],[Versiones corregidas20]],2,99)),0), IFERROR(VALUE(MID(Tabla[[#This Row],[Versiones corregidas21]],2,99)),0),IFERROR(VALUE(MID(#REF!,2,99)),0)) -> V0 | AM22: =IFERROR(_xlfn.XLOOKUP(Tabla[[#This Row],[¿En qué versión fue corregido?]],Versiones!$A$2:$A$34,Versiones!$B$2:$B$34),"No encontrado") -> No encontrado | AN22: {=IFERROR(_xlfn.XLOOKUP(TRUE,COUNTIF(Tabla[[#This Row],[Etiquetas]:[Etiquetas17]],Categorías!$A$2:$A$12)>0,Categorías!$A$2:$A$12),"No encontrado")} -> Funcional | AO22: {=IFERROR(INDEX(Funcionalidades!$A$2:$A$80,MATCH(TRUE, COUNTIF(Reporte_Gral!R22:Z22,Funcionalidades!$A$2:$A$80)>0,0)),"No encontrado")} -> Pago-De-Servicios-Con-Catálogo | AP22: =IF(AND(COUNTIF(Tabla[[#This Row],[Etiquetas]:[Etiquetas17]],"*UAT_V*")>0,COUNTIF(Tabla[[#This Row],[Etiquetas]:[Etiquetas17]],"*QA-Integración*")=0),"SI","") | AQ22: {=IF(Tabla[[#This Row],[Fue encontrado durante UAT?]]="SI",IFERROR(_xlfn.XLOOKUP(TRUE,ISNUMBER(SEARCH("UAT_V",Tabla[[#This Row],[Etiquetas]:[Etiquetas17]])),Tabla[[#This Row],[Etiquetas]:[Etiquetas17]]),""),"")} | AR22: =IF(COUNTIF(Tabla[[#This Row],[Etiquetas]:[Etiquetas17]],"*Devuelto*")>0,"SI","") | AS22: =COUNTIF(Tabla[[#This Row],[Etiquetas]:[Etiquetas17]],"*Devuelto*") -> 0
A23: Error | B23: T20-3681 | C23: 122511 | D23: BOT - El sistema permite realizar una entrega de valores aun cuando no hay dinero disponible, generando saldos negativos. | E23: Más alta | F23: Tareas por hacer | G23: T20 Sprint 26 2025 | R23: Entrega-de-Valores | S23: Funcional | T23: QA-IntegraciónV0.15 | U23: T3B20_BOT | V23: Tienda2.0 | W23: UAT | AA23: Yubisleinys Mora Vega | AB23: 46013.455 | AG23: BOT | AH23: PENDIENTES | AJ23: {=IFERROR(_xlfn.XLOOKUP(TRUE,COUNTIF(Tabla[[#This Row],[Etiquetas]:[Etiquetas17]],Versiones!$G$2:$G$36)>0,Versiones!$B$2:$B$36), "")} -> 25 | AK23: {=IFERROR(_xlfn.XLOOKUP(TRUE,COUNTIF(Tabla[[#This Row],[Etiquetas]:[Etiquetas17]],Versiones!$G$2:$G$36)>0,Versiones!$A$2:$A$36), "")} -> V0.15 | AL23: ="V"&MAX(IFERROR(VALUE(MID(Tabla[[#This Row],[Versiones corregidas]],2,99)),0), IFERROR(VALUE(MID(Tabla[[#This Row],[Versiones corregidas19]],2,99)),0), IFERROR(VALUE(MID(Tabla[[#This Row],[Versiones corregidas20]],2,99)),0), IFERROR(VALUE(MID(Tabla[[#This Row],[Versiones corregidas21]],2,99)),0),IFERROR(VALUE(MID(#REF!,2,99)),0)) -> V0 | AM23: =IFERROR(_xlfn.XLOOKUP(Tabla[[#This Row],[¿En qué versión fue corregido?]],Versiones!$A$2:$A$34,Versiones!$B$2:$B$34),"No encontrado") -> No encontrado | AN23: {=IFERROR(_xlfn.XLOOKUP(TRUE,COUNTIF(Tabla[[#This Row],[Etiquetas]:[Etiquetas17]],Categorías!$A$2:$A$12)>0,Categorías!$A$2:$A$12),"No encontrado")} -> Funcional | AO23: {=IFERROR(INDEX(Funcionalidades!$A$2:$A$80,MATCH(TRUE, COUNTIF(Reporte_Gral!R23:Z23,Funcionalidades!$A$2:$A$80)>0,0)),"No encontrado")} -> Entrega-De-Valores | AP23: =IF(AND(COUNTIF(Tabla[[#This Row],[Etiquetas]:[Etiquetas17]],"*UAT_V*")>0,COUNTIF(Tabla[[#This Row],[Etiquetas]:[Etiquetas17]],"*QA-Integración*")=0),"SI","") | AQ23: {=IF(Tabla[[#This Row],[Fue encontrado durante UAT?]]="SI",IFERROR(_xlfn.XLOOKUP(TRUE,ISNUMBER(SEARCH("UAT_V",Tabla[[#This Row],[Etiquetas]:[Etiquetas17]])),Tabla[[#This Row],[Etiquetas]:[Etiquetas17]]),""),"")} | AR23: =IF(COUNTIF(Tabla[[#This Row],[Etiquetas]:[Etiquetas17]],"*Devuelto*")>0,"SI","") | AS23: =COUNTIF(Tabla[[#This Row],[Etiquetas]:[Etiquetas17]],"*Devuelto*") -> 0
A24: Error | B24: T20-3670 | C24: 122248 | D24: BOT/POS - Cancelación de productos genera descuento incorrecto de stock y unidades vendidas erróneas en Dashboard de ventas | E24: Alta | F24: Tareas por hacer | R24: Eliminar-Artículo-De-Venta | S24: Funcional | T24: QA-IntegraciónV0.15 | AA24: Yubisleinys Mora Vega | AB24: 46010.61 | AG24: BOT | AH24: PENDIENTES | AJ24: {=IFERROR(_xlfn.XLOOKUP(TRUE,COUNTIF(Tabla[[#This Row],[Etiquetas]:[Etiquetas17]],Versiones!$G$2:$G$36)>0,Versiones!$B$2:$B$36), "")} -> 25 | AK24: {=IFERROR(_xlfn.XLOOKUP(TRUE,COUNTIF(Tabla[[#This Row],[Etiquetas]:[Etiquetas17]],Versiones!$G$2:$G$36)>0,Versiones!$A$2:$A$36), "")} -> V0.15 | AL24: ="V"&MAX(IFERROR(VALUE(MID(Tabla[[#This Row],[Versiones corregidas]],2,99)),0), IFERROR(VALUE(MID(Tabla[[#This Row],[Versiones corregidas19]],2,99)),0), IFERROR(VALUE(MID(Tabla[[#This Row],[Versiones corregidas20]],2,99)),0), IFERROR(VALUE(MID(Tabla[[#This Row],[Versiones corregidas21]],2,99)),0),IFERROR(VALUE(MID(#REF!,2,99)),0)) -> V0 | AM24: =IFERROR(_xlfn.XLOOKUP(Tabla[[#This Row],[¿En qué versión fue corregido?]],Versiones!$A$2:$A$34,Versiones!$B$2:$B$34),"No encontrado") -> No encontrado | AN24: {=IFERROR(_xlfn.XLOOKUP(TRUE,COUNTIF(Tabla[[#This Row],[Etiquetas]:[Etiquetas17]],Categorías!$A$2:$A$12)>0,Categorías!$A$2:$A$12),"No encontrado")} -> Funcional | AO24: {=IFERROR(INDEX(Funcionalidades!$A$2:$A$80,MATCH(TRUE, COUNTIF(Reporte_Gral!R24:Z24,Funcionalidades!$A$2:$A$80)>0,0)),"No encontrado")} -> Eliminar-Artículo-De-Venta | AP24: =IF(AND(COUNTIF(Tabla[[#This Row],[Etiquetas]:[Etiquetas17]],"*UAT_V*")>0,COUNTIF(Tabla[[#This Row],[Etiquetas]:[Etiquetas17]],"*QA-Integración*")=0),"SI","") | AQ24: {=IF(Tabla[[#This Row],[Fue encontrado durante UAT?]]="SI",IFERROR(_xlfn.XLOOKUP(TRUE,ISNUMBER(SEARCH("UAT_V",Tabla[[#This Row],[Etiquetas]:[Etiquetas17]])),Tabla[[#This Row],[Etiquetas]:[Etiquetas17]]),""),"")} | AR24: =IF(COUNTIF(Tabla[[#This Row],[Etiquetas]:[Etiquetas17]],"*Devuelto*")>0,"SI","") | AS24: =COUNTIF(Tabla[[#This Row],[Etiquetas]:[Etiquetas17]],"*Devuelto*") -> 0
A25: Error | B25: T20-3669 | C25: 122179 | D25: BOT - Modal Transferir mercancía no muestra botón para minimizar | E25: Medio | F25: Tareas por hacer | R25: Funcional | S25: QA-IntegraciónV0.15 | T25: Realizar-Transferencia | U25: Revisar_Diseño | AA25: Yubisleinys Mora Vega | AB25: 46010.48 | AG25: BOT | AH25: PENDIENTES | AJ25: {=IFERROR(_xlfn.XLOOKUP(TRUE,COUNTIF(Tabla[[#This Row],[Etiquetas]:[Etiquetas17]],Versiones!$G$2:$G$36)>0,Versiones!$B$2:$B$36), "")} -> 25 | AK25: {=IFERROR(_xlfn.XLOOKUP(TRUE,COUNTIF(Tabla[[#This Row],[Etiquetas]:[Etiquetas17]],Versiones!$G$2:$G$36)>0,Versiones!$A$2:$A$36), "")} -> V0.15 | AL25: ="V"&MAX(IFERROR(VALUE(MID(Tabla[[#This Row],[Versiones corregidas]],2,99)),0), IFERROR(VALUE(MID(Tabla[[#This Row],[Versiones corregidas19]],2,99)),0), IFERROR(VALUE(MID(Tabla[[#This Row],[Versiones corregidas20]],2,99)),0), IFERROR(VALUE(MID(Tabla[[#This Row],[Versiones corregidas21]],2,99)),0),IFERROR(VALUE(MID(#REF!,2,99)),0)) -> V0 | AM25: =IFERROR(_xlfn.XLOOKUP(Tabla[[#This Row],[¿En qué versión fue corregido?]],Versiones!$A$2:$A$34,Versiones!$B$2:$B$34),"No encontrado") -> No encontrado | AN25: {=IFERROR(_xlfn.XLOOKUP(TRUE,COUNTIF(Tabla[[#This Row],[Etiquetas]:[Etiquetas17]],Categorías!$A$2:$A$12)>0,Categorías!$A$2:$A$12),"No encontrado")} -> Funcional | AO25: {=IFERROR(INDEX(Funcionalidades!$A$2:$A$80,MATCH(TRUE, COUNTIF(Reporte_Gral!R25:Z25,Funcionalidades!$A$2:$A$80)>0,0)),"No encontrado")} -> Realizar-Transferencia | AP25: =IF(AND(COUNTIF(Tabla[[#This Row],[Etiquetas]:[Etiquetas17]],"*UAT_V*")>0,COUNTIF(Tabla[[#This Row],[Etiquetas]:[Etiquetas17]],"*QA-Integración*")=0),"SI","") | AQ25: {=IF(Tabla[[#This Row],[Fue encontrado durante UAT?]]="SI",IFERROR(_xlfn.XLOOKUP(TRUE,ISNUMBER(SEARCH("UAT_V",Tabla[[#This Row],[Etiquetas]:[Etiquetas17]])),Tabla[[#This Row],[Etiquetas]:[Etiquetas17]]),""),"")} | AR25: =IF(COUNTIF(Tabla[[#This Row],[Etiquetas]:[Etiquetas17]],"*Devuelto*")>0,"SI","") | AS25: =COUNTIF(Tabla[[#This Row],[Etiquetas]:[Etiquetas17]],"*Devuelto*") -> 0
A26: Error | B26: T20-3668 | C26: 122115 | D26: BOT - Modal Recibir mercancía no se visualiza botón para minimizar | E26: Alta | F26: Tareas por hacer | R26: Funcional | S26: QA-IntegraciónV0.15 | T26: Recibir-Mercancía-Almacén-Tienda | U26: Revisar_Diseño | AA26: Yubisleinys Mora Vega | AB26: 46010.382 | AG26: BOT | AH26: CANCELADO | AJ26: {=IFERROR(_xlfn.XLOOKUP(TRUE,COUNTIF(Tabla[[#This Row],[Etiquetas]:[Etiquetas17]],Versiones!$G$2:$G$36)>0,Versiones!$B$2:$B$36), "")} -> 25 | AK26: {=IFERROR(_xlfn.XLOOKUP(TRUE,COUNTIF(Tabla[[#This Row],[Etiquetas]:[Etiquetas17]],Versiones!$G$2:$G$36)>0,Versiones!$A$2:$A$36), "")} -> V0.15 | AL26: ="V"&MAX(IFERROR(VALUE(MID(Tabla[[#This Row],[Versiones corregidas]],2,99)),0), IFERROR(VALUE(MID(Tabla[[#This Row],[Versiones corregidas19]],2,99)),0), IFERROR(VALUE(MID(Tabla[[#This Row],[Versiones corregidas20]],2,99)),0), IFERROR(VALUE(MID(Tabla[[#This Row],[Versiones corregidas21]],2,99)),0),IFERROR(VALUE(MID(#REF!,2,99)),0)) -> V0 | AM26: =IFERROR(_xlfn.XLOOKUP(Tabla[[#This Row],[¿En qué versión fue corregido?]],Versiones!$A$2:$A$34,Versiones!$B$2:$B$34),"No encontrado") -> No encontrado | AN26: {=IFERROR(_xlfn.XLOOKUP(TRUE,COUNTIF(Tabla[[#This Row],[Etiquetas]:[Etiquetas17]],Categorías!$A$2:$A$12)>0,Categorías!$A$2:$A$12),"No encontrado")} -> Funcional | AO26: {=IFERROR(INDEX(Funcionalidades!$A$2:$A$80,MATCH(TRUE, COUNTIF(Reporte_Gral!R26:Z26,Funcionalidades!$A$2:$A$80)>0,0)),"No encontrado")} -> Recibir-Mercancía-Almacén-Tienda | AP26: =IF(AND(COUNTIF(Tabla[[#This Row],[Etiquetas]:[Etiquetas17]],"*UAT_V*")>0,COUNTIF(Tabla[[#This Row],[Etiquetas]:[Etiquetas17]],"*QA-Integración*")=0),"SI","") | AQ26: {=IF(Tabla[[#This Row],[Fue encontrado durante UAT?]]="SI",IFERROR(_xlfn.XLOOKUP(TRUE,ISNUMBER(SEARCH("UAT_V",Tabla[[#This Row],[Etiquetas]:[Etiquetas17]])),Tabla[[#This Row],[Etiquetas]:[Etiquetas17]]),""),"")} | AR26: =IF(COUNTIF(Tabla[[#This Row],[Etiquetas]:[Etiquetas17]],"*Devuelto*")>0,"SI","") | AS26: =COUNTIF(Tabla[[#This Row],[Etiquetas]:[Etiquetas17]],"*Devuelto*") -> 0
