Workbook

Sheet Detalle1
A1: Detalles de BUGS X - Prioridad: Alta, ¿En que Sprint fue encontrado?: Sprint 21, Estado: Tareas por hacer
A3: Tipo de Incidencia | B3: Clave de incidencia | C3: ID de la incidencia | D3: Resumen | E3: Principal | F3: Clave principal | G3: Parent summary | H3: Prioridad | I3: Estado | J3: Sprint | K3: Sprint_1 | L3: Sprint_2 | M3: Sprint_3 | N3: Sprint_4 | O3: Sprint_5 | P3: Etiquetas | Q3: Etiquetas_5 | R3: Etiquetas_6 | S3: Etiquetas_7 | T3: Etiquetas_8 | U3: Etiquetas_9 | V3: Etiquetas_10 | W3: Informador | X3: Creada | Y3: Versiones corregidas | Z3: Versiones corregidas_13 | AA3: Versiones corregidas_14 | AB3: Módulo | AC3: Desarrollador | AD3: Desarrollador_Bug_Cancelado | AE3: ¿En que Sprint fue encontrado? | AF3: ¿En qué versión fue corregido? | AG3: ¿En que Sprint fue corregido? | AH3: Categoría
A4: Error | B4: T20-2093 | C4: 102674 | D4: BOT - Panel Productos no se actualiza | E4: 87100 | F4: T20-1091 | G4: 4.- QA | H4: Alta | I4: Tareas por hacer | J4: T20 Sprint 21 2025 | P4: Funcional | Q4: QA-IntegraciónV0.9 | W4: Daniela Soto | X4: 45947.628 | AB4: BOT | AC4: Juan Munoz | AE4: Sprint 21 | AF4: v0 | AG4: N/A | AH4: Funcional

Sheet Detalle2
A1: Detalles de BUGS X - ¿En que Sprint fue encontrado?: Sprint 21
A3: Tipo de Incidencia | B3: Clave de incidencia | C3: ID de la incidencia | D3: Resumen | E3: Principal | F3: Clave principal | G3: Parent summary | H3: Prioridad | I3: Estado | J3: Sprint | K3: Sprint_1 | L3: Sprint_2 | M3: Sprint_3 | N3: Sprint_4 | O3: Sprint_5 | P3: Etiquetas | Q3: Etiquetas_5 | R3: Etiquetas_6 | S3: Etiquetas_7 | T3: Etiquetas_8 | U3: Etiquetas_9 | V3: Etiquetas_10 | W3: Informador | X3: Creada | Y3: Versiones corregidas | Z3: Versiones corregidas_13 | AA3: Versiones corregidas_14 | AB3: Módulo | AC3: Desarrollador | AD3: Desarrollador_Bug_Cancelado | AE3: ¿En que Sprint fue encontrado? | AF3: ¿En qué versión fue corregido? | AG3: ¿En que Sprint fue corregido? | AH3: Categoría
A4: Error | B4: T20-2093 | C4: 102674 | D4: BOT - Panel Productos no se actualiza | E4: 87100 | F4: T20-1091 | G4: 4.- QA | H4: Alta | I4: Tareas por hacer | J4: T20 Sprint 21 2025 | P4: Funcional | Q4: QA-IntegraciónV0.9 | W4: Daniela Soto | X4: 45947.628 | AB4: BOT | AC4: Juan Munoz | AE4: Sprint 21 | AF4: v0 | AG4: N/A | AH4: Funcional
A5: Error | B5: T20-2066 | C5: 102295 | D5: BOT - Modal pie de camión en inglés | E5: 87100 | F5: T20-1091 | G5: 4.- QA | H5: Medio | I5: Tareas por hacer | P5: Look&Feel | Q5: QA-IntegraciónV0.9 | W5: Daniela Soto | X5: 45946.557 | AB5: BOT | AC5: Juan Munoz | AE5: Sprint 21 | AF5: v0 | AG5: N/A | AH5: Look&Feel
A6: Error | B6: T20-2088 | C6: 102584 | D6: POS - Checar precio - Info en Inglés | E6: 87100 | F6: T20-1091 | G6: 4.- QA | H6: Medio | I6: Tareas por hacer | P6: Look&Feel | Q6: QA-IntegraciónV0.9 | W6: Daniela Soto | X6: 45947.383 | AB6: POS | AC6: Andres Vergara | AE6: Sprint 21 | AF6: v0 | AG6: N/A | AH6: Look&Feel
A7: Error | B7: T20-2089 | C7: 102586 | D7: POS - Pantalla principal - Info en inglés | E7: 87100 | F7: T20-1091 | G7: 4.- QA | H7: Medio | I7: Tareas por hacer | P7: Look&Feel | Q7: QA-IntegraciónV0.9 | W7: Daniela Soto | X7: 45947.399 | AB7: POS | AC7: Juan Munoz | AE7: Sprint 21 | AF7: v0 | AG7: N/A | AH7: Look&Feel
A8: Error | B8: T20-2094 | C8: 102710 | D8: Diferencias en tickets de venta - TC/Efectivo y Pago Mix | E8: 87100 | F8: T20-1091 | G8: 4.- QA | H8: Medio | I8: Tareas por hacer | J8: T20 Sprint 21 2025 | P8: Contenido/Datos | Q8: QA-IntegraciónV0.9 | W8: Carolina Rodríguez Soriano | X8: 45947.709 | AC8: Juan Munoz | AE8: Sprint 21 | AF8: v0 | AG8: N/A | AH8: Contenido/Datos

Sheet Tendencia
M1: Incidentes Totales X Estatus X Sprint
B3: Sprint | C3: Casos de Prueba Ejecutados | D3: Casos de prueba Pendientes | E3: Bugs Encontrados | F3: % Casos de Prueba Fallidos | G3: BUGS Cancelados | H3: Bugs Solucionados | I3: BUGS Pendientes por Resolver | J3: % Bugs Pendientes por resolver | M3: BUGS X | N3: ESTADO
B4: Sprint 16 | C4: 135 | E4: ='BUGS X SPRINT'!K7 -> 46 | F4: =+E4/C4 -> 0.34074074 | G4: =GETPIVOTDATA("Estado",$M$3,"Estado","Cancelado","¿En que Sprint fue encontrado?","Sprint 16") -> 7 | H4: 25 | I4: 14 | J4: =I4/E4 -> 0.30434783 | M4: SPRINT | N4: Cancelado | O4: Tareas por hacer | P4: Code Review | Q4: IN SIT | R4: READY FOR TESTING | S4: READY FOR UAT | T4: Blocked | U4: En curso | V4: TO BE DEPLOYED-SIT | W4: Total
B5: Sprint 17 | C5: 139 | E5: ='BUGS X SPRINT'!K8 -> 19 | F5: =+E5/C5 -> 0.13669065 | G5: =GETPIVOTDATA("Estado",$M$3,"Estado","Cancelado","¿En que Sprint fue encontrado?","Sprint 17") -> 2 | H5: 13 | I5: 4 | J5: =I5/E5 -> 0.21052632 | M5: Sprint 16 | N5: 7 | O5: 9 | P5: 3 | Q5: 1 | S5: 25 | T5: 1 | W5: 46
B6: Sprint 18 | C6: 105 | E6: ='BUGS X SPRINT'!K9 -> 28 | F6: =+E6/C6 -> 0.26666667 | G6: =GETPIVOTDATA("Estado",$M$3,"Estado","Cancelado","¿En que Sprint fue encontrado?","Sprint 18") -> 1 | H6: 12 | I6: 15 | J6: =I6/E6 -> 0.53571429 | M6: Sprint 17 | N6: 2 | O6: 4 | S6: 13 | W6: 19
B7: Sprint 19 | C7: 142 | E7: ='BUGS X SPRINT'!K10 -> 21 | F7: =+E7/C7 -> 0.14788732 | G7: =GETPIVOTDATA("Estado",$M$3,"Estado","Cancelado","¿En que Sprint fue encontrado?","Sprint 19") -> 2 | H7: 2 | I7: 17 | J7: =I7/E7 -> 0.80952381 | M7: Sprint 18 | N7: 1 | O7: 13 | P7: 1 | S7: 12 | T7: 1 | W7: 28
B8: Sprint 20 | C8: 136 | D8: * | E8: ='BUGS X SPRINT'!K11 -> 19 | F8: =+E8/C8 -> 0.13970588 | G8: =GETPIVOTDATA("Estado",$M$3,"Estado","Cancelado","¿En que Sprint fue encontrado?","Sprint 20") -> 4 | H8: 0 | I8: 15 | J8: =I8/E8 -> 0.78947368 | M8: Sprint 19 | N8: 2 | O8: 12 | R8: 1 | S8: 2 | V8: 4 | W8: 21
A9: En curso | B9: Sprint 21 | C9: 35 | E9: ='BUGS X SPRINT'!K12 -> 5 | F9: =+E9/C9 -> 0.14285714 | G9: 0 | H9: 0 | I9: 5 | J9: =I9/E9 -> 1 | M9: Sprint 20 | N9: 4 | O9: 11 | P9: 1 | T9: 1 | U9: 1 | V9: 1 | W9: 19
B10: Total | C10: =SUM(C4:C9) -> 692 | E10: =SUM(E4:E9) -> 138 | F10: =E10/C10 -> 0.19942197 | G10: =SUM(G4:G9) -> 16 | H10: =SUM(H4:H9) -> 52 | I10: =SUM(I4:I9) -> 70 | J10: =I10/E10 -> 0.50724638 | M10: Sprint 21 | O10: 5 | W10: 5
M11: Total | N11: 16 | O11: 54 | P11: 5 | Q11: 1 | R11: 1 | S11: 52 | T11: 3 | U11: 1 | V11: 5 | W11: 138

Sheet Reporte_Gral
A1: Tipo de Incidencia | B1: Clave de incidencia | C1: ID de la incidencia | D1: Resumen | E1: Principal | F1: Clave principal | G1: Parent summary | H1: Prioridad | I1: Estado | J1: Sprint | K1: Sprint_1 | L1: Sprint_2 | M1: Sprint_3 | N1: Sprint_4 | O1: Sprint_5 | P1: Etiquetas | Q1: Etiquetas_5 | R1: Etiquetas_6 | S1: Etiquetas_7 | T1: Etiquetas_8 | U1: Etiquetas_9 | V1: Etiquetas_10 | W1: Informador | X1: Creada | Y1: Versiones corregidas | Z1: Versiones corregidas_13 | AA1: Versiones corregidas_14 | AB1: Módulo | AC1: Desarrollador | AD1: Desarrollador_Bug_Cancelado | AE1: ¿En que Sprint fue encontrado? | AF1: ¿En qué versión fue corregido? | AG1: ¿En que Sprint fue corregido? | AH1: Categoría
A2: Error | B2: T20-958 | C2: 83062 | D2: BOT - Se valida el usuario con Entra ID | E2: 87100 | F2: T20-1091 | G2: 4.- QA | H2: Medio | I2: READY FOR UAT | J2: Backlog BUGS | P2: doc_ludo | Q2: Funcional | R2: QA-SmokeV0.4 | S2: T3B20_BOT | T2: T3B20_POS | U2: Tested_In_DEV | V2: Tienda2.0 | W2: Ludo | X2: 45873.228 | Y2: v0.5 | AB2: =IF(LEFT(Jira__32[[#This Row],[Resumen]],3)="POS","POS",IF(LEFT(Jira__32[[#This Row],[Resumen]],3)="BOT","BOT","")) -> BOT | AC2: Andres Vergara | AE2: {=_xlfn.IFS(OR(COUNTIF(P2:V2,Versiones!$G$9)>0, COUNTIF(P2:V2,Versiones!$H$8)>0), "Sprint 21",OR(COUNTIF(P2:V2,Versiones!$G$8)>0, COUNTIF(P2:V2,Versiones!$H$8)>0, COUNTIF(P2:V2,Versiones!$I$8)>0), "Sprint 20",OR(COUNTIF(P2:V2,Versiones!$G$7)>0, COUNTIF(P2:V2,Versiones!$H$7)>0, COUNTIF(P2:V2,Versiones!$I$7)>0), "Sprint 19",OR(COUNTIF(P2:V2,Versiones!$G$6)>0, COUNTIF(P2:V2,Versiones!$H$6)>0, COUNTIF(P2:V2,Versiones!$I$6)>0), "Sprint 18",OR(COUNTIF(P2:V2,Versiones!$G$4)>0, COUNTIF(P2:V2,Versiones!$H$4)>0, COUNTIF(P2:V2,Versiones!$G$5)>0, COUNTIF(P2:V2,Versiones!$H$5)>0), "Sprint 17",OR(COUNTIF(P2:V2,Versiones!$G$2)>0, COUNTIF(P2:V2,Versiones!$H$2)>0, COUNTIF(P2:V2,Versiones!$G$3)>0, COUNTIF(P2:V2,Versiones!$H$3)>0), "Sprint 16", OR(COUNTIF(P2:V2,Versiones!$G$2)>0, COUNTIF(P2:V2,Versiones!$H$2)>0, COUNTIF(P2:V2,Versiones!$G$3)>0, COUNTIF(P2:V2,Versiones!$H$3)>0), "Sprint 16",TRUE, "")} -> Sprint 16 | AF2: ="v"&MAX( IFERROR(VALUE(MID(Jira__32[[#This Row],[Versiones corregidas]],2,99)),0), IFERROR(VALUE(MID(Jira__32[[#This Row],[Versiones corregidas_13]],2,99)),0), IFERROR(VALUE(MID(Jira__32[[#This Row],[Versiones corregidas_14]],2,99)),0) ) -> v0.5 | AG2: {=_xlfn.IFS(Jira__32[[#This Row],[¿En qué versión fue corregido?]]="v0","N/A",Jira__32[[#This Row],[¿En qué versión fue corregido?]]="v0.4","Sprint 16", Jira__32[[#This Row],[¿En qué versión fue corregido?]]="v0.5","Sprint 17", Jira__32[[#This Row],[¿En qué versión fue corregido?]]="v0.6","Sprint 18", Jira__32[[#This Row],[¿En qué versión fue corregido?]]="v0.7","Sprint 19", Jira__32[[#This Row],[¿En qué versión fue corregido?]]="v0.8","Sprint 20",Jira__32[[#This Row],[¿En qué versión fue corregido?]]="v0.9","Sprint 21", TRUE,"Desconocido")} -> Sprint 17 | AH2: {=_xlfn.IFS(COUNTIF(P2:V2, Versiones!$A$13)>0, "Funcional", COUNTIF(P2:V2, Versiones!$A$14)>0, "Configuración", COUNTIF(P2:V2, Versiones!$A$15)>0, "Look&Feel", COUNTIF(P2:V2, Versiones!$A$16)>0, "Integración", COUNTIF(P2:V2, Versiones!$A$17)>0, "Contenido/Datos", COUNTIF(P2:V2, Versiones!$A$18)>0, "Eventos_Cosmos", COUNTIF(P2:V2, Versiones!$A$19)>0, "Eventos_iOT", COUNTIF(P2:V2, Versiones!$A$20)>0, "Eventos_Fabric", TRUE, "No encontrado")} -> Funcional
A3: Error | B3: T20-957 | C3: 83060 | D3: POS - Inicio de turno: corregir pantallas de monto de fondeo inicial | E3: 87100 | F3: T20-1091 | G3: 4.- QA | H3: Medio | I3: READY FOR UAT | J3: T20 Sprint 19 2025 | K3: Backlog BUGS | P3: doc_ludo | Q3: Look&Feel | R3: QA-SmokeV0.4 | S3: T3B20_POS | T3: Tienda2.0 | W3: Ludo | X3: 45873.219 | Y3: v0.7 | AB3: =IF(LEFT(Jira__32[[#This Row],[Resumen]],3)="POS","POS",IF(LEFT(Jira__32[[#This Row],[Resumen]],3)="BOT","BOT","")) -> POS | AC3: Ludovic Hern | AE3: {=_xlfn.IFS(OR(COUNTIF(P3:V3,Versiones!$G$9)>0, COUNTIF(P3:V3,Versiones!$H$8)>0), "Sprint 21",OR(COUNTIF(P3:V3,Versiones!$G$8)>0, COUNTIF(P3:V3,Versiones!$H$8)>0, COUNTIF(P3:V3,Versiones!$I$8)>0), "Sprint 20",OR(COUNTIF(P3:V3,Versiones!$G$7)>0, COUNTIF(P3:V3,Versiones!$H$7)>0, COUNTIF(P3:V3,Versiones!$I$7)>0), "Sprint 19",OR(COUNTIF(P3:V3,Versiones!$G$6)>0, COUNTIF(P3:V3,Versiones!$H$6)>0, COUNTIF(P3:V3,Versiones!$I$6)>0), "Sprint 18",OR(COUNTIF(P3:V3,Versiones!$G$4)>0, COUNTIF(P3:V3,Versiones!$H$4)>0, COUNTIF(P3:V3,Versiones!$G$5)>0, COUNTIF(P3:V3,Versiones!$H$5)>0), "Sprint 17",OR(COUNTIF(P3:V3,Versiones!$G$2)>0, COUNTIF(P3:V3,Versiones!$H$2)>0, COUNTIF(P3:V3,Versiones!$G$3)>0, COUNTIF(P3:V3,Versiones!$H$3)>0), "Sprint 16", OR(COUNTIF(P3:V3,Versiones!$G$2)>0, COUNTIF(P3:V3,Versiones!$H$2)>0, COUNTIF(P3:V3,Versiones!$G$3)>0, COUNTIF(P3:V3,Versiones!$H$3)>0), "Sprint 16",TRUE, "")} -> Sprint 16 | AF3: ="v"&MAX( IFERROR(VALUE(MID(Jira__32[[#This Row],[Versiones corregidas]],2,99)),0), IFERROR(VALUE(MID(Jira__32[[#This Row],[Versiones corregidas_13]],2,99)),0), IFERROR(VALUE(MID(Jira__32[[#This Row],[Versiones corregidas_14]],2,99)),0) ) -> v0.7 | AG3: {=_xlfn.IFS(Jira__32[[#This Row],[¿En qué versión fue corregido?]]="v0","N/A",Jira__32[[#This Row],[¿En qué versión fue corregido?]]="v0.4","Sprint 16", Jira__32[[#This Row],[¿En qué versión fue corregido?]]="v0.5","Sprint 17", Jira__32[[#This Row],[¿En qué versión fue corregido?]]="v0.6","Sprint 18", Jira__32[[#This Row],[¿En qué versión fue corregido?]]="v0.7","Sprint 19", Jira__32[[#This Row],[¿En qué versión fue corregido?]]="v0.8","Sprint 20",Jira__32[[#This Row],[¿En qué versión fue corregido?]]="v0.9","Sprint 21", TRUE,"Desconocido")} -> Sprint 19 | AH3: {=_xlfn.IFS(COUNTIF(P3:V3, Versiones!$A$13)>0, "Funcional", COUNTIF(P3:V3, Versiones!$A$14)>0, "Configuración", COUNTIF(P3:V3, Versiones!$A$15)>0, "Look&Feel", COUNTIF(P3:V3, Versiones!$A$16)>0, "Integración", COUNTIF(P3:V3, Versiones!$A$17)>0, "Contenido/Datos", COUNTIF(P3:V3, Versiones!$A$18)>0, "Eventos_Cosmos", COUNTIF(P3:V3, Versiones!$A$19)>0, "Eventos_iOT", COUNTIF(P3:V3, Versiones!$A$20)>0, "Eventos_Fabric", TRUE, "No encontrado")} -> Look&Feel
A4: Error | B4: T20-956 | C4: 83058 | D4: POS - Cierre de turno: permite ingresar monto para último alivio | E4: 87100 | F4: T20-1091 | G4: 4.- QA | H4: Medio | I4: Code Review | J4: Backlog BUGS | P4: doc_ludo | Q4: Funcional | R4: QA-SmokeV0.4 | S4: T3B20_POS | T4: Tienda2.0 | W4: Ludo | X4: 45873.197 | AB4: =IF(LEFT(Jira__32[[#This Row],[Resumen]],3)="POS","POS",IF(LEFT(Jira__32[[#This Row],[Resumen]],3)="BOT","BOT","")) -> POS | AC4: Ludovic Hern | AE4: {=_xlfn.IFS(OR(COUNTIF(P4:V4,Versiones!$G$9)>0, COUNTIF(P4:V4,Versiones!$H$8)>0), "Sprint 21",OR(COUNTIF(P4:V4,Versiones!$G$8)>0, COUNTIF(P4:V4,Versiones!$H$8)>0, COUNTIF(P4:V4,Versiones!$I$8)>0), "Sprint 20",OR(COUNTIF(P4:V4,Versiones!$G$7)>0, COUNTIF(P4:V4,Versiones!$H$7)>0, COUNTIF(P4:V4,Versiones!$I$7)>0), "Sprint 19",OR(COUNTIF(P4:V4,Versiones!$G$6)>0, COUNTIF(P4:V4,Versiones!$H$6)>0, COUNTIF(P4:V4,Versiones!$I$6)>0), "Sprint 18",OR(COUNTIF(P4:V4,Versiones!$G$4)>0, COUNTIF(P4:V4,Versiones!$H$4)>0, COUNTIF(P4:V4,Versiones!$G$5)>0, COUNTIF(P4:V4,Versiones!$H$5)>0), "Sprint 17",OR(COUNTIF(P4:V4,Versiones!$G$2)>0, COUNTIF(P4:V4,Versiones!$H$2)>0, COUNTIF(P4:V4,Versiones!$G$3)>0, COUNTIF(P4:V4,Versiones!$H$3)>0), "Sprint 16", OR(COUNTIF(P4:V4,Versiones!$G$2)>0, COUNTIF(P4:V4,Versiones!$H$2)>0, COUNTIF(P4:V4,Versiones!$G$3)>0, COUNTIF(P4:V4,Versiones!$H$3)>0), "Sprint 16",TRUE, "")} -> Sprint 16 | AF4: ="v"&MAX( IFERROR(VALUE(MID(Jira__32[[#This Row],[Versiones corregidas]],2,99)),0), IFERROR(VALUE(MID(Jira__32[[#This Row],[Versiones corregidas_13]],2,99)),0), IFERROR(VALUE(MID(Jira__32[[#This Row],[Versiones corregidas_14]],2,99)),0) ) -> v0 | AG4: {=_xlfn.IFS(Jira__32[[#This Row],[¿En qué versión fue corregido?]]="v0","N/A",Jira__32[[#This Row],[¿En qué versión fue corregido?]]="v0.4","Sprint 16", Jira__32[[#This Row],[¿En qué versión fue corregido?]]="v0.5","Sprint 17", Jira__32[[#This Row],[¿En qué versión fue corregido?]]="v0.6","Sprint 18", Jira__32[[#This Row],[¿En qué versión fue corregido?]]="v0.7","Sprint 19", Jira__32[[#This Row],[¿En qué versión fue corregido?]]="v0.8","Sprint 20",Jira__32[[#This Row],[¿En qué versión fue corregido?]]="v0.9","Sprint 21", TRUE,"Desconocido")} -> N/A | AH4: {=_xlfn.IFS(COUNTIF(P4:V4, Versiones!$A$13)>0, "Funcional", COUNTIF(P4:V4, Versiones!$A$14)>0, "Configuración", COUNTIF(P4:V4, Versiones!$A$15)>0, "Look&Feel", COUNTIF(P4:V4, Versiones!$A$16)>0, "Integración", COUNTIF(P4:V4, Versiones!$A$17)>0, "Contenido/Datos", COUNTIF(P4:V4, Versiones!$A$18)>0, "Eventos_Cosmos", COUNTIF(P4:V4, Versiones!$A$19)>0, "Eventos_iOT", COUNTIF(P4:V4, Versiones!$A$20)>0, "Eventos_Fabric", TRUE, "No encontrado")} -> Funcional
A5: Error | B5: T20-955 | C5: 83056 | D5: POS - Cierre de turno: autenticación del encargado de turno | E5: 87100 | F5: T20-1091 | G5: 4.- QA | H5: Medio | I5: Code Review | J5: Backlog BUGS | P5: doc_ludo | Q5: Funcional | R5: QA-SmokeV0.4 | S5: T3B20_POS | T5: Tienda2.0 | W5: Ludo | X5: 45873.194 | AB5: =IF(LEFT(Jira__32[[#This Row],[Resumen]],3)="POS","POS",IF(LEFT(Jira__32[[#This Row],[Resumen]],3)="BOT","BOT","")) -> POS | AC5: Ludovic Hern | AE5: {=_xlfn.IFS(OR(COUNTIF(P5:V5,Versiones!$G$9)>0, COUNTIF(P5:V5,Versiones!$H$8)>0), "Sprint 21",OR(COUNTIF(P5:V5,Versiones!$G$8)>0, COUNTIF(P5:V5,Versiones!$H$8)>0, COUNTIF(P5:V5,Versiones!$I$8)>0), "Sprint 20",OR(COUNTIF(P5:V5,Versiones!$G$7)>0, COUNTIF(P5:V5,Versiones!$H$7)>0, COUNTIF(P5:V5,Versiones!$I$7)>0), "Sprint 19",OR(COUNTIF(P5:V5,Versiones!$G$6)>0, COUNTIF(P5:V5,Versiones!$H$6)>0, COUNTIF(P5:V5,Versiones!$I$6)>0), "Sprint 18",OR(COUNTIF(P5:V5,Versiones!$G$4)>0, COUNTIF(P5:V5,Versiones!$H$4)>0, COUNTIF(P5:V5,Versiones!$G$5)>0, COUNTIF(P5:V5,Versiones!$H$5)>0), "Sprint 17",OR(COUNTIF(P5:V5,Versiones!$G$2)>0, COUNTIF(P5:V5,Versiones!$H$2)>0, COUNTIF(P5:V5,Versiones!$G$3)>0, COUNTIF(P5:V5,Versiones!$H$3)>0), "Sprint 16", OR(COUNTIF(P5:V5,Versiones!$G$2)>0, COUNTIF(P5:V5,Versiones!$H$2)>0, COUNTIF(P5:V5,Versiones!$G$3)>0, COUNTIF(P5:V5,Versiones!$H$3)>0), "Sprint 16",TRUE, "")} -> Sprint 16 | AF5: ="v"&MAX( IFERROR(VALUE(MID(Jira__32[[#This Row],[Versiones corregidas]],2,99)),0), IFERROR(VALUE(MID(Jira__32[[#This Row],[Versiones corregidas_13]],2,99)),0), IFERROR(VALUE(MID(Jira__32[[#This Row],[Versiones corregidas_14]],2,99)),0) ) -> v0 | AG5: {=_xlfn.IFS(Jira__32[[#This Row],[¿En qué versión fue corregido?]]="v0","N/A",Jira__32[[#This Row],[¿En qué versión fue corregido?]]="v0.4","Sprint 16", Jira__32[[#This Row],[¿En qué versión fue corregido?]]="v0.5","Sprint 17", Jira__32[[#This Row],[¿En qué versión fue corregido?]]="v0.6","Sprint 18", Jira__32[[#This Row],[¿En qué versión fue corregido?]]="v0.7","Sprint 19", Jira__32[[#This Row],[¿En qué versión fue corregido?]]="v0.8","Sprint 20",Jira__32[[#This Row],[¿En qué versión fue corregido?]]="v0.9","Sprint 21", TRUE,"Desconocido")} -> N/A | AH5: {=_xlfn.IFS(COUNTIF(P5:V5, Versiones!$A$13)>0, "Funcional", COUNTIF(P5:V5, Versiones!$A$14)>0, "Configuración", COUNTIF(P5:V5, Versiones!$A$15)>0, "Look&Feel", COUNTIF(P5:V5, Versiones!$A$16)>0, "Integración", COUNTIF(P5:V5, Versiones!$A$17)>0, "Contenido/Datos", COUNTIF(P5:V5, Versiones!$A$18)>0, "Eventos_Cosmos", COUNTIF(P5:V5, Versiones!$A$19)>0, "Eventos_iOT", COUNTIF(P5:V5, Versiones!$A$20)>0, "Eventos_Fabric", TRUE, "No encontrado")} -> Funcional
A6: Error | B6: T20-954 | C6: 83054 | D6: BOT - Modal de confirmación de cierre de día no aparece | E6: 87100 | F6: T20-1091 | G6: 4.- QA | H6: Alta | I6: Blocked | J6: T20 Sprint 17 2025 | K6: T20 Sprint 18 2025 | L6: T20 Sprint 21 2025 | P6: doc_ludo | Q6: Look&Feel | R6: QA | S6: QA-SmokeV0.4 | T6: T3B20_BOT | U6: Tienda2.0 | W6: Maria Pilar Albacete Occhi | X6: 45873.172 | Y6: v0.5 | Z6: v0.6 | AA6: v0.7 | AB6: =IF(LEFT(Jira__32[[#This Row],[Resumen]],3)="POS","POS",IF(LEFT(Jira__32[[#This Row],[Resumen]],3)="BOT","BOT","")) -> BOT | AC6: Ludovic Hern | AE6: {=_xlfn.IFS(OR(COUNTIF(P6:V6,Versiones!$G$9)>0, COUNTIF(P6:V6,Versiones!$H$8)>0), "Sprint 21",OR(COUNTIF(P6:V6,Versiones!$G$8)>0, COUNTIF(P6:V6,Versiones!$H$8)>0, COUNTIF(P6:V6,Versiones!$I$8)>0), "Sprint 20",OR(COUNTIF(P6:V6,Versiones!$G$7)>0, COUNTIF(P6:V6,Versiones!$H$7)>0, COUNTIF(P6:V6,Versiones!$I$7)>0), "Sprint 19",OR(COUNTIF(P6:V6,Versiones!$G$6)>0, COUNTIF(P6:V6,Versiones!$H$6)>0, COUNTIF(P6:V6,Versiones!$I$6)>0), "Sprint 18",OR(COUNTIF(P6:V6,Versiones!$G$4)>0, COUNTIF(P6:V6,Versiones!$H$4)>0, COUNTIF(P6:V6,Versiones!$G$5)>0, COUNTIF(P6:V6,Versiones!$H$5)>0), "Sprint 17",OR(COUNTIF(P6:V6,Versiones!$G$2)>0, COUNTIF(P6:V6,Versiones!$H$2)>0, COUNTIF(P6:V6,Versiones!$G$3)>0, COUNTIF(P6:V6,Versiones!$H$3)>0), "Sprint 16", OR(COUNTIF(P6:V6,Versiones!$G$2)>0, COUNTIF(P6:V6,Versiones!$H$2)>0, COUNTIF(P6:V6,Versiones!$G$3)>0, COUNTIF(P6:V6,Versiones!$H$3)>0), "Sprint 16",TRUE, "")} -> Sprint 16 | AF6: ="v"&MAX( IFERROR(VALUE(MID(Jira__32[[#This Row],[Versiones corregidas]],2,99)),0), IFERROR(VALUE(MID(Jira__32[[#This Row],[Versiones corregidas_13]],2,99)),0), IFERROR(VALUE(MID(Jira__32[[#This Row],[Versiones corregidas_14]],2,99)),0) ) -> v0.7 | AG6: {=_xlfn.IFS(Jira__32[[#This Row],[¿En qué versión fue corregido?]]="v0","N/A",Jira__32[[#This Row],[¿En qué versión fue corregido?]]="v0.4","Sprint 16", Jira__32[[#This Row],[¿En qué versión fue corregido?]]="v0.5","Sprint 17", Jira__32[[#This Row],[¿En qué versión fue corregido?]]="v0.6","Sprint 18", Jira__32[[#This Row],[¿En qué versión fue corregido?]]="v0.7","Sprint 19", Jira__32[[#This Row],[¿En qué versión fue corregido?]]="v0.8","Sprint 20",Jira__32[[#This Row],[¿En qué versión fue corregido?]]="v0.9","Sprint 21", TRUE,"Desconocido")} -> Sprint 19 | AH6: {=_xlfn.IFS(COUNTIF(P6:V6, Versiones!$A$13)>0, "Funcional", COUNTIF(P6:V6, Versiones!$A$14)>0, "Configuración", COUNTIF(P6:V6, Versiones!$A$15)>0, "Look&Feel", COUNTIF(P6:V6, Versiones!$A$16)>0, "Integración", COUNTIF(P6:V6, Versiones!$A$17)>0, "Contenido/Datos", COUNTIF(P6:V6, Versiones!$A$18)>0, "Eventos_Cosmos", COUNTIF(P6:V6, Versiones!$A$19)>0, "Eventos_iOT", COUNTIF(P6:V6, Versiones!$A$20)>0, "Eventos_Fabric", TRUE, "No encontrado")} -> Look&Feel
A7: Error | B7: T20-953 | C7: 83052 | D7: BOT - Inicio+Cierre de día: correcciones en el flujo | E7: 79941 | F7: T20-623 | G7: 3.-Desarrollo POS/BOT /CDM | H7: Medio | I7: Tareas por hacer | J7: T20 Sprint 16 2025 | K7: T20 Sprint 17 2025 | L7: T20 Sprint 18 2025 | M7: Backlog BUGS | P7: Funcional | Q7: QA | R7: QA-SmokeV0.4 | S7: T3B20_BOT | T7: Tienda2.0 | W7: Ludo | X7: 45873.169 | Y7: v0.6 | Z7: v0.7 | AB7: =IF(LEFT(Jira__32[[#This Row],[Resumen]],3)="POS","POS",IF(LEFT(Jira__32[[#This Row],[Resumen]],3)="BOT","BOT","")) -> BOT | AC7: Ludovic Hern | AE7: {=_xlfn.IFS(OR(COUNTIF(P7:V7,Versiones!$G$9)>0, COUNTIF(P7:V7,Versiones!$H$8)>0), "Sprint 21",OR(COUNTIF(P7:V7,Versiones!$G$8)>0, COUNTIF(P7:V7,Versiones!$H$8)>0, COUNTIF(P7:V7,Versiones!$I$8)>0), "Sprint 20",OR(COUNTIF(P7:V7,Versiones!$G$7)>0, COUNTIF(P7:V7,Versiones!$H$7)>0, COUNTIF(P7:V7,Versiones!$I$7)>0), "Sprint 19",OR(COUNTIF(P7:V7,Versiones!$G$6)>0, COUNTIF(P7:V7,Versiones!$H$6)>0, COUNTIF(P7:V7,Versiones!$I$6)>0), "Sprint 18",OR(COUNTIF(P7:V7,Versiones!$G$4)>0, COUNTIF(P7:V7,Versiones!$H$4)>0, COUNTIF(P7:V7,Versiones!$G$5)>0, COUNTIF(P7:V7,Versiones!$H$5)>0), "Sprint 17",OR(COUNTIF(P7:V7,Versiones!$G$2)>0, COUNTIF(P7:V7,Versiones!$H$2)>0, COUNTIF(P7:V7,Versiones!$G$3)>0, COUNTIF(P7:V7,Versiones!$H$3)>0), "Sprint 16", OR(COUNTIF(P7:V7,Versiones!$G$2)>0, COUNTIF(P7:V7,Versiones!$H$2)>0, COUNTIF(P7:V7,Versiones!$G$3)>0, COUNTIF(P7:V7,Versiones!$H$3)>0), "Sprint 16",TRUE, "")} -> Sprint 16 | AF7: ="v"&MAX( IFERROR(VALUE(MID(Jira__32[[#This Row],[Versiones corregidas]],2,99)),0), IFERROR(VALUE(MID(Jira__32[[#This Row],[Versiones corregidas_13]],2,99)),0), IFERROR(VALUE(MID(Jira__32[[#This Row],[Versiones corregidas_14]],2,99)),0) ) -> v0.7 | AG7: {=_xlfn.IFS(Jira__32[[#This Row],[¿En qué versión fue corregido?]]="v0","N/A",Jira__32[[#This Row],[¿En qué versión fue corregido?]]="v0.4","Sprint 16", Jira__32[[#This Row],[¿En qué versión fue corregido?]]="v0.5","Sprint 17", Jira__32[[#This Row],[¿En qué versión fue corregido?]]="v0.6","Sprint 18", Jira__32[[#This Row],[¿En qué versión fue corregido?]]="v0.7","Sprint 19", Jira__32[[#This Row],[¿En qué versión fue corregido?]]="v0.8","Sprint 20",Jira__32[[#This Row],[¿En qué versión fue corregido?]]="v0.9","Sprint 21", TRUE,"Desconocido")} -> Sprint 19 | AH7: {=_xlfn.IFS(COUNTIF(P7:V7, Versiones!$A$13)>0, "Funcional", COUNTIF(P7:V7, Versiones!$A$14)>0, "Configuración", COUNTIF(P7:V7, Versiones!$A$15)>0, "Look&Feel", COUNTIF(P7:V7, Versiones!$A$16)>0, "Integración", COUNTIF(P7:V7, Versiones!$A$17)>0, "Contenido/Datos", COUNTIF(P7:V7, Versiones!$A$18)>0, "Eventos_Cosmos", COUNTIF(P7:V7, Versiones!$A$19)>0, "Eventos_iOT", COUNTIF(P7:V7, Versiones!$A$20)>0, "Eventos_Fabric", TRUE, "No encontrado")} -> Funcional
A8: Error | B8: T20-951 | C8: 83049 | D8: POS - Generar evento de devolución (= ticket) (blocked) | E8: 87100 | F8: T20-1091 | G8: 4.- QA | H8: Medio | I8: READY FOR UAT | J8: T20 Sprint 18 2025 | K8: Backlog BUGS | P8: Eventos_iOT | Q8: Integración | R8: QA | S8: QA-SmokeV0.4 | T8: T3B20_POS | U8: Tienda2.0 | W8: Ludo | X8: 45873.149 | Y8: v0.7 | AB8: =IF(LEFT(Jira__32[[#This Row],[Resumen]],3)="POS","POS",IF(LEFT(Jira__32[[#This Row],[Resumen]],3)="BOT","BOT","")) -> POS | AC8: Juan Munoz | AE8: {=_xlfn.IFS(OR(COUNTIF(P8:V8,Versiones!$G$9)>0, COUNTIF(P8:V8,Versiones!$H$8)>0), "Sprint 21",OR(COUNTIF(P8:V8,Versiones!$G$8)>0, COUNTIF(P8:V8,Versiones!$H$8)>0, COUNTIF(P8:V8,Versiones!$I$8)>0), "Sprint 20",OR(COUNTIF(P8:V8,Versiones!$G$7)>0, COUNTIF(P8:V8,Versiones!$H$7)>0, COUNTIF(P8:V8,Versiones!$I$7)>0), "Sprint 19",OR(COUNTIF(P8:V8,Versiones!$G$6)>0, COUNTIF(P8:V8,Versiones!$H$6)>0, COUNTIF(P8:V8,Versiones!$I$6)>0), "Sprint 18",OR(COUNTIF(P8:V8,Versiones!$G$4)>0, COUNTIF(P8:V8,Versiones!$H$4)>0, COUNTIF(P8:V8,Versiones!$G$5)>0, COUNTIF(P8:V8,Versiones!$H$5)>0), "Sprint 17",OR(COUNTIF(P8:V8,Versiones!$G$2)>0, COUNTIF(P8:V8,Versiones!$H$2)>0, COUNTIF(P8:V8,Versiones!$G$3)>0, COUNTIF(P8:V8,Versiones!$H$3)>0), "Sprint 16", OR(COUNTIF(P8:V8,Versiones!$G$2)>0, COUNTIF(P8:V8,Versiones!$H$2)>0, COUNTIF(P8:V8,Versiones!$G$3)>0, COUNTIF(P8:V8,Versiones!$H$3)>0), "Sprint 16",TRUE, "")} -> Sprint 16 | AF8: ="v"&MAX( IFERROR(VALUE(MID(Jira__32[[#This Row],[Versiones corregidas]],2,99)),0), IFERROR(VALUE(MID(Jira__32[[#This Row],[Versiones corregidas_13]],2,99)),0), IFERROR(VALUE(MID(Jira__32[[#This Row],[Versiones corregidas_14]],2,99)),0) ) -> v0.7 | AG8: {=_xlfn.IFS(Jira__32[[#This Row],[¿En qué versión fue corregido?]]="v0","N/A",Jira__32[[#This Row],[¿En qué versión fue corregido?]]="v0.4","Sprint 16", Jira__32[[#This Row],[¿En qué versión fue corregido?]]="v0.5","Sprint 17", Jira__32[[#This Row],[¿En qué versión fue corregido?]]="v0.6","Sprint 18", Jira__32[[#This Row],[¿En qué versión fue corregido?]]="v0.7","Sprint 19", Jira__32[[#This Row],[¿En qué versión fue corregido?]]="v0.8","Sprint 20",Jira__32[[#This Row],[¿En qué versión fue corregido?]]="v0.9","Sprint 21", TRUE,"Desconocido")} -> Sprint 19 | AH8: {=_xlfn.IFS(COUNTIF(P8:V8, Versiones!$A$13)>0, "Funcional", COUNTIF(P8:V8, Versiones!$A$14)>0, "Configuración", COUNTIF(P8:V8, Versiones!$A$15)>0, "Look&Feel", COUNTIF(P8:V8, Versiones!$A$16)>0, "Integración", COUNTIF(P8:V8, Versiones!$A$17)>0, "Contenido/Datos", COUNTIF(P8:V8, Versiones!$A$18)>0, "Eventos_Cosmos", COUNTIF(P8:V8, Versiones!$A$19)>0, "Eventos_iOT", COUNTIF(P8:V8, Versiones!$A$20)>0, "Eventos_Fabric", TRUE, "No encontrado")} -> Integración
A9: Error | B9: T20-949 | C9: 83046 | D9: BOT - Validar una declaración de merma: guardar en DB + generar evento | E9: 87100 | F9: T20-1091 | G9: 4.- QA | H9: Medio | I9: Tareas por hacer | J9: Backlog BUGS | P9: doc_ludo | Q9: Integración | R9: QA-SmokeV0.4 | S9: T3B20_BOT | T9: Tienda2.0 | W9: Ludo | X9: 45873.131 | Y9: v0.5 | AB9: =IF(LEFT(Jira__32[[#This Row],[Resumen]],3)="POS","POS",IF(LEFT(Jira__32[[#This Row],[Resumen]],3)="BOT","BOT","")) -> BOT | AC9: PENDIENTES | AE9: {=_xlfn.IFS(OR(COUNTIF(P9:V9,Versiones!$G$9)>0, COUNTIF(P9:V9,Versiones!$H$8)>0), "Sprint 21",OR(COUNTIF(P9:V9,Versiones!$G$8)>0, COUNTIF(P9:V9,Versiones!$H$8)>0, COUNTIF(P9:V9,Versiones!$I$8)>0), "Sprint 20",OR(COUNTIF(P9:V9,Versiones!$G$7)>0, COUNTIF(P9:V9,Versiones!$H$7)>0, COUNTIF(P9:V9,Versiones!$I$7)>0), "Sprint 19",OR(COUNTIF(P9:V9,Versiones!$G$6)>0, COUNTIF(P9:V9,Versiones!$H$6)>0, COUNTIF(P9:V9,Versiones!$I$6)>0), "Sprint 18",OR(COUNTIF(P9:V9,Versiones!$G$4)>0, COUNTIF(P9:V9,Versiones!$H$4)>0, COUNTIF(P9:V9,Versiones!$G$5)>0, COUNTIF(P9:V9,Versiones!$H$5)>0), "Sprint 17",OR(COUNTIF(P9:V9,Versiones!$G$2)>0, COUNTIF(P9:V9,Versiones!$H$2)>0, COUNTIF(P9:V9,Versiones!$G$3)>0, COUNTIF(P9:V9,Versiones!$H$3)>0), "Sprint 16", OR(COUNTIF(P9:V9,Versiones!$G$2)>0, COUNTIF(P9:V9,Versiones!$H$2)>0, COUNTIF(P9:V9,Versiones!$G$3)>0, COUNTIF(P9:V9,Versiones!$H$3)>0), "Sprint 16",TRUE, "")} -> Sprint 16 | AF9: ="v"&MAX( IFERROR(VALUE(MID(Jira__32[[#This Row],[Versiones corregidas]],2,99)),0), IFERROR(VALUE(MID(Jira__32[[#This Row],[Versiones corregidas_13]],2,99)),0), IFERROR(VALUE(MID(Jira__32[[#This Row],[Versiones corregidas_14]],2,99)),0) ) -> v0.5 | AG9: {=_xlfn.IFS(Jira__32[[#This Row],[¿En qué versión fue corregido?]]="v0","N/A",Jira__32[[#This Row],[¿En qué versión fue corregido?]]="v0.4","Sprint 16", Jira__32[[#This Row],[¿En qué versión fue corregido?]]="v0.5","Sprint 17", Jira__32[[#This Row],[¿En qué versión fue corregido?]]="v0.6","Sprint 18", Jira__32[[#This Row],[¿En qué versión fue corregido?]]="v0.7","Sprint 19", Jira__32[[#This Row],[¿En qué versión fue corregido?]]="v0.8","Sprint 20",Jira__32[[#This Row],[¿En qué versión fue corregido?]]="v0.9","Sprint 21", TRUE,"Desconocido")} -> Sprint 17 | AH9: {=_xlfn.IFS(COUNTIF(P9:V9, Versiones!$A$13)>0, "Funcional", COUNTIF(P9:V9, Versiones!$A$14)>0, "Configuración", COUNTIF(P9:V9, Versiones!$A$15)>0, "Look&Feel", COUNTIF(P9:V9, Versiones!$A$16)>0, "Integración", COUNTIF(P9:V9, Versiones!$A$17)>0, "Contenido/Datos", COUNTIF(P9:V9, Versiones!$A$18)>0, "Eventos_Cosmos", COUNTIF(P9:V9, Versiones!$A$19)>0, "Eventos_iOT", COUNTIF(P9:V9, Versiones!$A$20)>0, "Eventos_Fabric", TRUE, "No encontrado")} -> Integración
A10: Error | B10: T20-948 | C10: 83044 | D10: BOT - Ingresar cantidad a mermar | E10: 87100 | F10: T20-1091 | G10: 4.- QA | H10: Medio | I10: READY FOR UAT | J10: Backlog BUGS | P10: doc_ludo | Q10: Funcional | R10: QA-SmokeV0.4 | S10: T3B20_BOT | T10: Tienda2.0 | W10: Ludo | X10: 45873.129 | Y10: v0.5 | AB10: =IF(LEFT(Jira__32[[#This Row],[Resumen]],3)="POS","POS",IF(LEFT(Jira__32[[#This Row],[Resumen]],3)="BOT","BOT","")) -> BOT | AC10: Juan Munoz | AE10: {=_xlfn.IFS(OR(COUNTIF(P10:V10,Versiones!$G$9)>0, COUNTIF(P10:V10,Versiones!$H$8)>0), "Sprint 21",OR(COUNTIF(P10:V10,Versiones!$G$8)>0, COUNTIF(P10:V10,Versiones!$H$8)>0, COUNTIF(P10:V10,Versiones!$I$8)>0), "Sprint 20",OR(COUNTIF(P10:V10,Versiones!$G$7)>0, COUNTIF(P10:V10,Versiones!$H$7)>0, COUNTIF(P10:V10,Versiones!$I$7)>0), "Sprint 19",OR(COUNTIF(P10:V10,Versiones!$G$6)>0, COUNTIF(P10:V10,Versiones!$H$6)>0, COUNTIF(P10:V10,Versiones!$I$6)>0), "Sprint 18",OR(COUNTIF(P10:V10,Versiones!$G$4)>0, COUNTIF(P10:V10,Versiones!$H$4)>0, COUNTIF(P10:V10,Versiones!$G$5)>0, COUNTIF(P10:V10,Versiones!$H$5)>0), "Sprint 17",OR(COUNTIF(P10:V10,Versiones!$G$2)>0, COUNTIF(P10:V10,Versiones!$H$2)>0, COUNTIF(P10:V10,Versiones!$G$3)>0, COUNTIF(P10:V10,Versiones!$H$3)>0), "Sprint 16", OR(COUNTIF(P10:V10,Versiones!$G$2)>0, COUNTIF(P10:V10,Versiones!$H$2)>0, COUNTIF(P10:V10,Versiones!$G$3)>0, COUNTIF(P10:V10,Versiones!$H$3)>0), "Sprint 16",TRUE, "")} -> Sprint 16 | AF10: ="v"&MAX( IFERROR(VALUE(MID(Jira__32[[#This Row],[Versiones corregidas]],2,99)),0), IFERROR(VALUE(MID(Jira__32[[#This Row],[Versiones corregidas_13]],2,99)),0), IFERROR(VALUE(MID(Jira__32[[#This Row],[Versiones corregidas_14]],2,99)),0) ) -> v0.5 | AG10: {=_xlfn.IFS(Jira__32[[#This Row],[¿En qué versión fue corregido?]]="v0","N/A",Jira__32[[#This Row],[¿En qué versión fue corregido?]]="v0.4","Sprint 16", Jira__32[[#This Row],[¿En qué versión fue corregido?]]="v0.5","Sprint 17", Jira__32[[#This Row],[¿En qué versión fue corregido?]]="v0.6","Sprint 18", Jira__32[[#This Row],[¿En qué versión fue corregido?]]="v0.7","Sprint 19", Jira__32[[#This Row],[¿En qué versión fue corregido?]]="v0.8","Sprint 20",Jira__32[[#This Row],[¿En qué versión fue corregido?]]="v0.9","Sprint 21", TRUE,"Desconocido")} -> Sprint 17 | AH10: {=_xlfn.IFS(COUNTIF(P10:V10, Versiones!$A$13)>0, "Funcional", COUNTIF(P10:V10, Versiones!$A$14)>0, "Configuración", COUNTIF(P10:V10, Versiones!$A$15)>0, "Look&Feel", COUNTIF(P10:V10, Versiones!$A$16)>0, "Integración", COUNTIF(P10:V10, Versiones!$A$17)>0, "Contenido/Datos", COUNTIF(P10:V10, Versiones!$A$18)>0, "Eventos_Cosmos", COUNTIF(P10:V10, Versiones!$A$19)>0, "Eventos_iOT", COUNTIF(P10:V10, Versiones!$A$20)>0, "Eventos_Fabric", TRUE, "No encontrado")} -> Funcional
A11: Error | B11: T20-947 | C11: 83042 | D11: BOT - Dropdown de motivo de merma | E11: 87100 | F11: T20-1091 | G11: 4.- QA | H11: Medio | I11: Tareas por hacer | J11: Backlog BUGS | P11: doc_ludo | Q11: Funcional | R11: QA-SmokeV0.4 | S11: T3B20_BOT | T11: Tienda2.0 | W11: Ludo | X11: 45873.128 | Y11: v0.5 | AB11: =IF(LEFT(Jira__32[[#This Row],[Resumen]],3)="POS","POS",IF(LEFT(Jira__32[[#This Row],[Resumen]],3)="BOT","BOT","")) -> BOT | AC11: PENDIENTES | AE11: {=_xlfn.IFS(OR(COUNTIF(P11:V11,Versiones!$G$9)>0, COUNTIF(P11:V11,Versiones!$H$8)>0), "Sprint 21",OR(COUNTIF(P11:V11,Versiones!$G$8)>0, COUNTIF(P11:V11,Versiones!$H$8)>0, COUNTIF(P11:V11,Versiones!$I$8)>0), "Sprint 20",OR(COUNTIF(P11:V11,Versiones!$G$7)>0, COUNTIF(P11:V11,Versiones!$H$7)>0, COUNTIF(P11:V11,Versiones!$I$7)>0), "Sprint 19",OR(COUNTIF(P11:V11,Versiones!$G$6)>0, COUNTIF(P11:V11,Versiones!$H$6)>0, COUNTIF(P11:V11,Versiones!$I$6)>0), "Sprint 18",OR(COUNTIF(P11:V11,Versiones!$G$4)>0, COUNTIF(P11:V11,Versiones!$H$4)>0, COUNTIF(P11:V11,Versiones!$G$5)>0, COUNTIF(P11:V11,Versiones!$H$5)>0), "Sprint 17",OR(COUNTIF(P11:V11,Versiones!$G$2)>0, COUNTIF(P11:V11,Versiones!$H$2)>0, COUNTIF(P11:V11,Versiones!$G$3)>0, COUNTIF(P11:V11,Versiones!$H$3)>0), "Sprint 16", OR(COUNTIF(P11:V11,Versiones!$G$2)>0, COUNTIF(P11:V11,Versiones!$H$2)>0, COUNTIF(P11:V11,Versiones!$G$3)>0, COUNTIF(P11:V11,Versiones!$H$3)>0), "Sprint 16",TRUE, "")} -> Sprint 16 | AF11: ="v"&MAX( IFERROR(VALUE(MID(Jira__32[[#This Row],[Versiones corregidas]],2,99)),0), IFERROR(VALUE(MID(Jira__32[[#This Row],[Versiones corregidas_13]],2,99)),0), IFERROR(VALUE(MID(Jira__32[[#This Row],[Versiones corregidas_14]],2,99)),0) ) -> v0.5 | AG11: {=_xlfn.IFS(Jira__32[[#This Row],[¿En qué versión fue corregido?]]="v0","N/A",Jira__32[[#This Row],[¿En qué versión fue corregido?]]="v0.4","Sprint 16", Jira__32[[#This Row],[¿En qué versión fue corregido?]]="v0.5","Sprint 17", Jira__32[[#This Row],[¿En qué versión fue corregido?]]="v0.6","Sprint 18", Jira__32[[#This Row],[¿En qué versión fue corregido?]]="v0.7","Sprint 19", Jira__32[[#This Row],[¿En qué versión fue corregido?]]="v0.8","Sprint 20",Jira__32[[#This Row],[¿En qué versión fue corregido?]]="v0.9","Sprint 21", TRUE,"Desconocido")} -> Sprint 17 | AH11: {=_xlfn.IFS(COUNTIF(P11:V11, Versiones!$A$13)>0, "Funcional", COUNTIF(P11:V11, Versiones!$A$14)>0, "Configuración", COUNTIF(P11:V11, Versiones!$A$15)>0, "Look&Feel", COUNTIF(P11:V11, Versiones!$A$16)>0, "Integración", COUNTIF(P11:V11, Versiones!$A$17)>0, "Contenido/Datos", COUNTIF(P11:V11, Versiones!$A$18)>0, "Eventos_Cosmos", COUNTIF(P11:V11, Versiones!$A$19)>0, "Eventos_iOT", COUNTIF(P11:V11, Versiones!$A$20)>0, "Eventos_Fabric", TRUE, "No encontrado")} -> Funcional
A12: Error | B12: T20-945 | C12: 83039 | D12: POS - Buscar y agregar producto | E12: 87100 | F12: T20-1091 | G12: 4.- QA | H12: Medio | I12: READY FOR UAT | P12: doc_ludo | Q12: Funcional | R12: QA-SmokeV0.4 | S12: T3B20_POS | T12: Tested_In_DEV | U12: Tienda2.0 | W12: Ludo | X12: 45873.107 | Y12: v0.5 | AB12: =IF(LEFT(Jira__32[[#This Row],[Resumen]],3)="POS","POS",IF(LEFT(Jira__32[[#This Row],[Resumen]],3)="BOT","BOT","")) -> POS | AC12: Juan Munoz | AE12: {=_xlfn.IFS(OR(COUNTIF(P12:V12,Versiones!$G$9)>0, COUNTIF(P12:V12,Versiones!$H$8)>0), "Sprint 21",OR(COUNTIF(P12:V12,Versiones!$G$8)>0, COUNTIF(P12:V12,Versiones!$H$8)>0, COUNTIF(P12:V12,Versiones!$I$8)>0), "Sprint 20",OR(COUNTIF(P12:V12,Versiones!$G$7)>0, COUNTIF(P12:V12,Versiones!$H$7)>0, COUNTIF(P12:V12,Versiones!$I$7)>0), "Sprint 19",OR(COUNTIF(P12:V12,Versiones!$G$6)>0, COUNTIF(P12:V12,Versiones!$H$6)>0, COUNTIF(P12:V12,Versiones!$I$6)>0), "Sprint 18",OR(COUNTIF(P12:V12,Versiones!$G$4)>0, COUNTIF(P12:V12,Versiones!$H$4)>0, COUNTIF(P12:V12,Versiones!$G$5)>0, COUNTIF(P12:V12,Versiones!$H$5)>0), "Sprint 17",OR(COUNTIF(P12:V12,Versiones!$G$2)>0, COUNTIF(P12:V12,Versiones!$H$2)>0, COUNTIF(P12:V12,Versiones!$G$3)>0, COUNTIF(P12:V12,Versiones!$H$3)>0), "Sprint 16", OR(COUNTIF(P12:V12,Versiones!$G$2)>0, COUNTIF(P12:V12,Versiones!$H$2)>0, COUNTIF(P12:V12,Versiones!$G$3)>0, COUNTIF(P12:V12,Versiones!$H$3)>0), "Sprint 16",TRUE, "")} -> Sprint 16 | AF12: ="v"&MAX( IFERROR(VALUE(MID(Jira__32[[#This Row],[Versiones corregidas]],2,99)),0), IFERROR(VALUE(MID(Jira__32[[#This Row],[Versiones corregidas_13]],2,99)),0), IFERROR(VALUE(MID(Jira__32[[#This Row],[Versiones corregidas_14]],2,99)),0) ) -> v0.5 | AG12: {=_xlfn.IFS(Jira__32[[#This Row],[¿En qué versión fue corregido?]]="v0","N/A",Jira__32[[#This Row],[¿En qué versión fue corregido?]]="v0.4","Sprint 16", Jira__32[[#This Row],[¿En qué versión fue corregido?]]="v0.5","Sprint 17", Jira__32[[#This Row],[¿En qué versión fue corregido?]]="v0.6","Sprint 18", Jira__32[[#This Row],[¿En qué versión fue corregido?]]="v0.7","Sprint 19", Jira__32[[#This Row],[¿En qué versión fue corregido?]]="v0.8","Sprint 20",Jira__32[[#This Row],[¿En qué versión fue corregido?]]="v0.9","Sprint 21", TRUE,"Desconocido")} -> Sprint 17 | AH12: {=_xlfn.IFS(COUNTIF(P12:V12, Versiones!$A$13)>0, "Funcional", COUNTIF(P12:V12, Versiones!$A$14)>0, "Configuración", COUNTIF(P12:V12, Versiones!$A$15)>0, "Look&Feel", COUNTIF(P12:V12, Versiones!$A$16)>0, "Integración", COUNTIF(P12:V12, Versiones!$A$17)>0, "Contenido/Datos", COUNTIF(P12:V12, Versiones!$A$18)>0, "Eventos_Cosmos", COUNTIF(P12:V12, Versiones!$A$19)>0, "Eventos_iOT", COUNTIF(P12:V12, Versiones!$A$20)>0, "Eventos_Fabric", TRUE, "No encontrado")} -> Funcional
A13: Error | B13: T20-943 | C13: 83035 | D13: POS - Eliminar articulo de venta: corrección del flujo | E13: 87100 | F13: T20-1091 | G13: 4.- QA | H13: Medio | I13: IN SIT | J13: Backlog BUGS | P13: doc_ludo | Q13: Funcional | R13: QA-SmokeV0.4 | S13: T3B20_POS | T13: Tested_In_DEV | U13: Tienda2.0 | W13: Ludo | X13: 45873.095 | Y13: v0.5 | AB13: =IF(LEFT(Jira__32[[#This Row],[Resumen]],3)="POS","POS",IF(LEFT(Jira__32[[#This Row],[Resumen]],3)="BOT","BOT","")) -> POS | AC13: Andres Vergara | AE13: {=_xlfn.IFS(OR(COUNTIF(P13:V13,Versiones!$G$9)>0, COUNTIF(P13:V13,Versiones!$H$8)>0), "Sprint 21",OR(COUNTIF(P13:V13,Versiones!$G$8)>0, COUNTIF(P13:V13,Versiones!$H$8)>0, COUNTIF(P13:V13,Versiones!$I$8)>0), "Sprint 20",OR(COUNTIF(P13:V13,Versiones!$G$7)>0, COUNTIF(P13:V13,Versiones!$H$7)>0, COUNTIF(P13:V13,Versiones!$I$7)>0), "Sprint 19",OR(COUNTIF(P13:V13,Versiones!$G$6)>0, COUNTIF(P13:V13,Versiones!$H$6)>0, COUNTIF(P13:V13,Versiones!$I$6)>0), "Sprint 18",OR(COUNTIF(P13:V13,Versiones!$G$4)>0, COUNTIF(P13:V13,Versiones!$H$4)>0, COUNTIF(P13:V13,Versiones!$G$5)>0, COUNTIF(P13:V13,Versiones!$H$5)>0), "Sprint 17",OR(COUNTIF(P13:V13,Versiones!$G$2)>0, COUNTIF(P13:V13,Versiones!$H$2)>0, COUNTIF(P13:V13,Versiones!$G$3)>0, COUNTIF(P13:V13,Versiones!$H$3)>0), "Sprint 16", OR(COUNTIF(P13:V13,Versiones!$G$2)>0, COUNTIF(P13:V13,Versiones!$H$2)>0, COUNTIF(P13:V13,Versiones!$G$3)>0, COUNTIF(P13:V13,Versiones!$H$3)>0), "Sprint 16",TRUE, "")} -> Sprint 16 | AF13: ="v"&MAX( IFERROR(VALUE(MID(Jira__32[[#This Row],[Versiones corregidas]],2,99)),0), IFERROR(VALUE(MID(Jira__32[[#This Row],[Versiones corregidas_13]],2,99)),0), IFERROR(VALUE(MID(Jira__32[[#This Row],[Versiones corregidas_14]],2,99)),0) ) -> v0.5 | AG13: {=_xlfn.IFS(Jira__32[[#This Row],[¿En qué versión fue corregido?]]="v0","N/A",Jira__32[[#This Row],[¿En qué versión fue corregido?]]="v0.4","Sprint 16", Jira__32[[#This Row],[¿En qué versión fue corregido?]]="v0.5","Sprint 17", Jira__32[[#This Row],[¿En qué versión fue corregido?]]="v0.6","Sprint 18", Jira__32[[#This Row],[¿En qué versión fue corregido?]]="v0.7","Sprint 19", Jira__32[[#This Row],[¿En qué versión fue corregido?]]="v0.8","Sprint 20",Jira__32[[#This Row],[¿En qué versión fue corregido?]]="v0.9","Sprint 21", TRUE,"Desconocido")} -> Sprint 17 | AH13: {=_xlfn.IFS(COUNTIF(P13:V13, Versiones!$A$13)>0, "Funcional", COUNTIF(P13:V13, Versiones!$A$14)>0, "Configuración", COUNTIF(P13:V13, Versiones!$A$15)>0, "Look&Feel", COUNTIF(P13:V13, Versiones!$A$16)>0, "Integración", COUNTIF(P13:V13, Versiones!$A$17)>0, "Contenido/Datos", COUNTIF(P13:V13, Versiones!$A$18)>0, "Eventos_Cosmos", COUNTIF(P13:V13, Versiones!$A$19)>0, "Eventos_iOT", COUNTIF(P13:V13, Versiones!$A$20)>0, "Eventos_Fabric", TRUE, "No encontrado")} -> Funcional
A14: Error | B14: T20-942 | C14: 83033 | D14: POS - Indicar el cambio a dar al cliente cuando paga con efectivo | E14: 87100 | F14: T20-1091 | G14: 4.- QA | H14: Medio | I14: READY FOR UAT | J14: T20 Sprint 18 2025 | K14: Backlog BUGS | P14: doc_ludo | Q14: Funcional | R14: QA-SmokeV0.4 | S14: T3B20_POS | T14: Tienda2.0 | W14: Ludo | X14: 45873.062 | Y14: v0.6 | AB14: =IF(LEFT(Jira__32[[#This Row],[Resumen]],3)="POS","POS",IF(LEFT(Jira__32[[#This Row],[Resumen]],3)="BOT","BOT","")) -> POS | AC14: Juan Munoz | AE14: {=_xlfn.IFS(OR(COUNTIF(P14:V14,Versiones!$G$9)>0, COUNTIF(P14:V14,Versiones!$H$8)>0), "Sprint 21",OR(COUNTIF(P14:V14,Versiones!$G$8)>0, COUNTIF(P14:V14,Versiones!$H$8)>0, COUNTIF(P14:V14,Versiones!$I$8)>0), "Sprint 20",OR(COUNTIF(P14:V14,Versiones!$G$7)>0, COUNTIF(P14:V14,Versiones!$H$7)>0, COUNTIF(P14:V14,Versiones!$I$7)>0), "Sprint 19",OR(COUNTIF(P14:V14,Versiones!$G$6)>0, COUNTIF(P14:V14,Versiones!$H$6)>0, COUNTIF(P14:V14,Versiones!$I$6)>0), "Sprint 18",OR(COUNTIF(P14:V14,Versiones!$G$4)>0, COUNTIF(P14:V14,Versiones!$H$4)>0, COUNTIF(P14:V14,Versiones!$G$5)>0, COUNTIF(P14:V14,Versiones!$H$5)>0), "Sprint 17",OR(COUNTIF(P14:V14,Versiones!$G$2)>0, COUNTIF(P14:V14,Versiones!$H$2)>0, COUNTIF(P14:V14,Versiones!$G$3)>0, COUNTIF(P14:V14,Versiones!$H$3)>0), "Sprint 16", OR(COUNTIF(P14:V14,Versiones!$G$2)>0, COUNTIF(P14:V14,Versiones!$H$2)>0, COUNTIF(P14:V14,Versiones!$G$3)>0, COUNTIF(P14:V14,Versiones!$H$3)>0), "Sprint 16",TRUE, "")} -> Sprint 16 | AF14: ="v"&MAX( IFERROR(VALUE(MID(Jira__32[[#This Row],[Versiones corregidas]],2,99)),0), IFERROR(VALUE(MID(Jira__32[[#This Row],[Versiones corregidas_13]],2,99)),0), IFERROR(VALUE(MID(Jira__32[[#This Row],[Versiones corregidas_14]],2,99)),0) ) -> v0.6 | AG14: {=_xlfn.IFS(Jira__32[[#This Row],[¿En qué versión fue corregido?]]="v0","N/A",Jira__32[[#This Row],[¿En qué versión fue corregido?]]="v0.4","Sprint 16", Jira__32[[#This Row],[¿En qué versión fue corregido?]]="v0.5","Sprint 17", Jira__32[[#This Row],[¿En qué versión fue corregido?]]="v0.6","Sprint 18", Jira__32[[#This Row],[¿En qué versión fue corregido?]]="v0.7","Sprint 19", Jira__32[[#This Row],[¿En qué versión fue corregido?]]="v0.8","Sprint 20",Jira__32[[#This Row],[¿En qué versión fue corregido?]]="v0.9","Sprint 21", TRUE,"Desconocido")} -> Sprint 18 | AH14: {=_xlfn.IFS(COUNTIF(P14:V14, Versiones!$A$13)>0, "Funcional", COUNTIF(P14:V14, Versiones!$A$14)>0, "Configuración", COUNTIF(P14:V14, Versiones!$A$15)>0, "Look&Feel", COUNTIF(P14:V14, Versiones!$A$16)>0, "Integración", COUNTIF(P14:V14, Versiones!$A$17)>0, "Contenido/Datos", COUNTIF(P14:V14, Versiones!$A$18)>0, "Eventos_Cosmos", COUNTIF(P14:V14, Versiones!$A$19)>0, "Eventos_iOT", COUNTIF(P14:V14, Versiones!$A$20)>0, "Eventos_Fabric", TRUE, "No encontrado")} -> Funcional
A15: Error | B15: T20-940 | C15: 83030 | D15: POS - Shortcuts ya no funcionan en flujo de pago | E15: 87100 | F15: T20-1091 | G15: 4.- QA | H15: Medio | I15: Tareas por hacer | J15: Backlog BUGS | P15: doc_ludo | Q15: Funcional | R15: QA-SmokeV0.4 | S15: T3B20_POS | T15: Tienda2.0 | W15: Ludo | X15: 45873.053 | Y15: v0.5 | AB15: =IF(LEFT(Jira__32[[#This Row],[Resumen]],3)="POS","POS",IF(LEFT(Jira__32[[#This Row],[Resumen]],3)="BOT","BOT","")) -> POS | AC15: PENDIENTES | AE15: {=_xlfn.IFS(OR(COUNTIF(P15:V15,Versiones!$G$9)>0, COUNTIF(P15:V15,Versiones!$H$8)>0), "Sprint 21",OR(COUNTIF(P15:V15,Versiones!$G$8)>0, COUNTIF(P15:V15,Versiones!$H$8)>0, COUNTIF(P15:V15,Versiones!$I$8)>0), "Sprint 20",OR(COUNTIF(P15:V15,Versiones!$G$7)>0, COUNTIF(P15:V15,Versiones!$H$7)>0, COUNTIF(P15:V15,Versiones!$I$7)>0), "Sprint 19",OR(COUNTIF(P15:V15,Versiones!$G$6)>0, COUNTIF(P15:V15,Versiones!$H$6)>0, COUNTIF(P15:V15,Versiones!$I$6)>0), "Sprint 18",OR(COUNTIF(P15:V15,Versiones!$G$4)>0, COUNTIF(P15:V15,Versiones!$H$4)>0, COUNTIF(P15:V15,Versiones!$G$5)>0, COUNTIF(P15:V15,Versiones!$H$5)>0), "Sprint 17",OR(COUNTIF(P15:V15,Versiones!$G$2)>0, COUNTIF(P15:V15,Versiones!$H$2)>0, COUNTIF(P15:V15,Versiones!$G$3)>0, COUNTIF(P15:V15,Versiones!$H$3)>0), "Sprint 16", OR(COUNTIF(P15:V15,Versiones!$G$2)>0, COUNTIF(P15:V15,Versiones!$H$2)>0, COUNTIF(P15:V15,Versiones!$G$3)>0, COUNTIF(P15:V15,Versiones!$H$3)>0), "Sprint 16",TRUE, "")} -> Sprint 16 | AF15: ="v"&MAX( IFERROR(VALUE(MID(Jira__32[[#This Row],[Versiones corregidas]],2,99)),0), IFERROR(VALUE(MID(Jira__32[[#This Row],[Versiones corregidas_13]],2,99)),0), IFERROR(VALUE(MID(Jira__32[[#This Row],[Versiones corregidas_14]],2,99)),0) ) -> v0.5 | AG15: {=_xlfn.IFS(Jira__32[[#This Row],[¿En qué versión fue corregido?]]="v0","N/A",Jira__32[[#This Row],[¿En qué versión fue corregido?]]="v0.4","Sprint 16", Jira__32[[#This Row],[¿En qué versión fue corregido?]]="v0.5","Sprint 17", Jira__32[[#This Row],[¿En qué versión fue corregido?]]="v0.6","Sprint 18", Jira__32[[#This Row],[¿En qué versión fue corregido?]]="v0.7","Sprint 19", Jira__32[[#This Row],[¿En qué versión fue corregido?]]="v0.8","Sprint 20",Jira__32[[#This Row],[¿En qué versión fue corregido?]]="v0.9","Sprint 21", TRUE,"Desconocido")} -> Sprint 17 | AH15: {=_xlfn.IFS(COUNTIF(P15:V15, Versiones!$A$13)>0, "Funcional", COUNTIF(P15:V15, Versiones!$A$14)>0, "Configuración", COUNTIF(P15:V15, Versiones!$A$15)>0, "Look&Feel", COUNTIF(P15:V15, Versiones!$A$16)>0, "Integración", COUNTIF(P15:V15, Versiones!$A$17)>0, "Contenido/Datos", COUNTIF(P15:V15, Versiones!$A$18)>0, "Eventos_Cosmos", COUNTIF(P15:V15, Versiones!$A$19)>0, "Eventos_iOT", COUNTIF(P15:V15, Versiones!$A$20)>0, "Eventos_Fabric", TRUE, "No encontrado")} -> Funcional
A16: Error | B16: T20-939 | C16: 83028 | D16: POS - Shortcuts invertidos para opciones de pago | E16: 87100 | F16: T20-1091 | G16: 4.- QA | H16: Medio | I16: READY FOR UAT | J16: Backlog BUGS | P16: doc_ludo | Q16: Funcional | R16: QA-SmokeV0.4 | S16: T3B20_POS | T16: Tested_In_DEV | U16: Tienda2.0 | W16: Ludo | X16: 45873.051 | Y16: v0.5 | AB16: =IF(LEFT(Jira__32[[#This Row],[Resumen]],3)="POS","POS",IF(LEFT(Jira__32[[#This Row],[Resumen]],3)="BOT","BOT","")) -> POS | AC16: Andres Vergara | AE16: {=_xlfn.IFS(OR(COUNTIF(P16:V16,Versiones!$G$9)>0, COUNTIF(P16:V16,Versiones!$H$8)>0), "Sprint 21",OR(COUNTIF(P16:V16,Versiones!$G$8)>0, COUNTIF(P16:V16,Versiones!$H$8)>0, COUNTIF(P16:V16,Versiones!$I$8)>0), "Sprint 20",OR(COUNTIF(P16:V16,Versiones!$G$7)>0, COUNTIF(P16:V16,Versiones!$H$7)>0, COUNTIF(P16:V16,Versiones!$I$7)>0), "Sprint 19",OR(COUNTIF(P16:V16,Versiones!$G$6)>0, COUNTIF(P16:V16,Versiones!$H$6)>0, COUNTIF(P16:V16,Versiones!$I$6)>0), "Sprint 18",OR(COUNTIF(P16:V16,Versiones!$G$4)>0, COUNTIF(P16:V16,Versiones!$H$4)>0, COUNTIF(P16:V16,Versiones!$G$5)>0, COUNTIF(P16:V16,Versiones!$H$5)>0), "Sprint 17",OR(COUNTIF(P16:V16,Versiones!$G$2)>0, COUNTIF(P16:V16,Versiones!$H$2)>0, COUNTIF(P16:V16,Versiones!$G$3)>0, COUNTIF(P16:V16,Versiones!$H$3)>0), "Sprint 16", OR(COUNTIF(P16:V16,Versiones!$G$2)>0, COUNTIF(P16:V16,Versiones!$H$2)>0, COUNTIF(P16:V16,Versiones!$G$3)>0, COUNTIF(P16:V16,Versiones!$H$3)>0), "Sprint 16",TRUE, "")} -> Sprint 16 | AF16: ="v"&MAX( IFERROR(VALUE(MID(Jira__32[[#This Row],[Versiones corregidas]],2,99)),0), IFERROR(VALUE(MID(Jira__32[[#This Row],[Versiones corregidas_13]],2,99)),0), IFERROR(VALUE(MID(Jira__32[[#This Row],[Versiones corregidas_14]],2,99)),0) ) -> v0.5 | AG16: {=_xlfn.IFS(Jira__32[[#This Row],[¿En qué versión fue corregido?]]="v0","N/A",Jira__32[[#This Row],[¿En qué versión fue corregido?]]="v0.4","Sprint 16", Jira__32[[#This Row],[¿En qué versión fue corregido?]]="v0.5","Sprint 17", Jira__32[[#This Row],[¿En qué versión fue corregido?]]="v0.6","Sprint 18", Jira__32[[#This Row],[¿En qué versión fue corregido?]]="v0.7","Sprint 19", Jira__32[[#This Row],[¿En qué versión fue corregido?]]="v0.8","Sprint 20",Jira__32[[#This Row],[¿En qué versión fue corregido?]]="v0.9","Sprint 21", TRUE,"Desconocido")} -> Sprint 17 | AH16: {=_xlfn.IFS(COUNTIF(P16:V16, Versiones!$A$13)>0, "Funcional", COUNTIF(P16:V16, Versiones!$A$14)>0, "Configuración", COUNTIF(P16:V16, Versiones!$A$15)>0, "Look&Feel", COUNTIF(P16:V16, Versiones!$A$16)>0, "Integración", COUNTIF(P16:V16, Versiones!$A$17)>0, "Contenido/Datos", COUNTIF(P16:V16, Versiones!$A$18)>0, "Eventos_Cosmos", COUNTIF(P16:V16, Versiones!$A$19)>0, "Eventos_iOT", COUNTIF(P16:V16, Versiones!$A$20)>0, "Eventos_Fabric", TRUE, "No encontrado")} -> Funcional
A17: Error | B17: T20-937 | C17: 83024 | D17: POS- Los modals de autenticación validan las credenciales | E17: 87100 | F17: T20-1091 | G17: 4.- QA | H17: Medio | I17: Cancelado | P17: doc_ludo | Q17: Funcional | R17: QA-SmokeV0.4 | S17: T3B20_BOT | T17: T3B20_POS | U17: Tested_In_DEV | V17: Tienda2.0 | W17: Ludo | X17: 45873.037 | Y17: v0.5 | AB17: =IF(LEFT(Jira__32[[#This Row],[Resumen]],3)="POS","POS",IF(LEFT(Jira__32[[#This Row],[Resumen]],3)="BOT","BOT","")) -> POS | AC17: CANCELADO | AE17: {=_xlfn.IFS(OR(COUNTIF(P17:V17,Versiones!$G$9)>0, COUNTIF(P17:V17,Versiones!$H$8)>0), "Sprint 21",OR(COUNTIF(P17:V17,Versiones!$G$8)>0, COUNTIF(P17:V17,Versiones!$H$8)>0, COUNTIF(P17:V17,Versiones!$I$8)>0), "Sprint 20",OR(COUNTIF(P17:V17,Versiones!$G$7)>0, COUNTIF(P17:V17,Versiones!$H$7)>0, COUNTIF(P17:V17,Versiones!$I$7)>0), "Sprint 19",OR(COUNTIF(P17:V17,Versiones!$G$6)>0, COUNTIF(P17:V17,Versiones!$H$6)>0, COUNTIF(P17:V17,Versiones!$I$6)>0), "Sprint 18",OR(COUNTIF(P17:V17,Versiones!$G$4)>0, COUNTIF(P17:V17,Versiones!$H$4)>0, COUNTIF(P17:V17,Versiones!$G$5)>0, COUNTIF(P17:V17,Versiones!$H$5)>0), "Sprint 17",OR(COUNTIF(P17:V17,Versiones!$G$2)>0, COUNTIF(P17:V17,Versiones!$H$2)>0, COUNTIF(P17:V17,Versiones!$G$3)>0, COUNTIF(P17:V17,Versiones!$H$3)>0), "Sprint 16", OR(COUNTIF(P17:V17,Versiones!$G$2)>0, COUNTIF(P17:V17,Versiones!$H$2)>0, COUNTIF(P17:V17,Versiones!$G$3)>0, COUNTIF(P17:V17,Versiones!$H$3)>0), "Sprint 16",TRUE, "")} -> Sprint 16 | AF17: ="v"&MAX( IFERROR(VALUE(MID(Jira__32[[#This Row],[Versiones corregidas]],2,99)),0), IFERROR(VALUE(MID(Jira__32[[#This Row],[Versiones corregidas_13]],2,99)),0), IFERROR(VALUE(MID(Jira__32[[#This Row],[Versiones corregidas_14]],2,99)),0) ) -> v0.5 | AG17: {=_xlfn.IFS(Jira__32[[#This Row],[¿En qué versión fue corregido?]]="v0","N/A",Jira__32[[#This Row],[¿En qué versión fue corregido?]]="v0.4","Sprint 16", Jira__32[[#This Row],[¿En qué versión fue corregido?]]="v0.5","Sprint 17", Jira__32[[#This Row],[¿En qué versión fue corregido?]]="v0.6","Sprint 18", Jira__32[[#This Row],[¿En qué versión fue corregido?]]="v0.7","Sprint 19", Jira__32[[#This Row],[¿En qué versión fue corregido?]]="v0.8","Sprint 20",Jira__32[[#This Row],[¿En qué versión fue corregido?]]="v0.9","Sprint 21", TRUE,"Desconocido")} -> Sprint 17 | AH17: {=_xlfn.IFS(COUNTIF(P17:V17, Versiones!$A$13)>0, "Funcional", COUNTIF(P17:V17, Versiones!$A$14)>0, "Configuración", COUNTIF(P17:V17, Versiones!$A$15)>0, "Look&Feel", COUNTIF(P17:V17, Versiones!$A$16)>0, "Integración", COUNTIF(P17:V17, Versiones!$A$17)>0, "Contenido/Datos", COUNTIF(P17:V17, Versiones!$A$18)>0, "Eventos_Cosmos", COUNTIF(P17:V17, Versiones!$A$19)>0, "Eventos_iOT", COUNTIF(P17:V17, Versiones!$A$20)>0, "Eventos_Fabric", TRUE, "No encontrado")} -> Funcional
A18: Error | B18: T20-936 | C18: 83022 | D18: POS - No se pueden realizar multiples devoluciones | E18: 87100 | F18: T20-1091 | G18: 4.- QA | H18: Alta | I18: Tareas por hacer | J18: T20 Sprint 21 2025 | P18: Funcional | Q18: QA-SmokeV0.4 | W18: Ludo | X18: 45873.034 | Y18: v0.5 | AB18: =IF(LEFT(Jira__32[[#This Row],[Resumen]],3)="POS","POS",IF(LEFT(Jira__32[[#This Row],[Resumen]],3)="BOT","BOT","")) -> POS | AC18: PENDIENTES | AE18: {=_xlfn.IFS(OR(COUNTIF(P18:V18,Versiones!$G$9)>0, COUNTIF(P18:V18,Versiones!$H$8)>0), "Sprint 21",OR(COUNTIF(P18:V18,Versiones!$G$8)>0, COUNTIF(P18:V18,Versiones!$H$8)>0, COUNTIF(P18:V18,Versiones!$I$8)>0), "Sprint 20",OR(COUNTIF(P18:V18,Versiones!$G$7)>0, COUNTIF(P18:V18,Versiones!$H$7)>0, COUNTIF(P18:V18,Versiones!$I$7)>0), "Sprint 19",OR(COUNTIF(P18:V18,Versiones!$G$6)>0, COUNTIF(P18:V18,Versiones!$H$6)>0, COUNTIF(P18:V18,Versiones!$I$6)>0), "Sprint 18",OR(COUNTIF(P18:V18,Versiones!$G$4)>0, COUNTIF(P18:V18,Versiones!$H$4)>0, COUNTIF(P18:V18,Versiones!$G$5)>0, COUNTIF(P18:V18,Versiones!$H$5)>0), "Sprint 17",OR(COUNTIF(P18:V18,Versiones!$G$2)>0, COUNTIF(P18:V18,Versiones!$H$2)>0, COUNTIF(P18:V18,Versiones!$G$3)>0, COUNTIF(P18:V18,Versiones!$H$3)>0), "Sprint 16", OR(COUNTIF(P18:V18,Versiones!$G$2)>0, COUNTIF(P18:V18,Versiones!$H$2)>0, COUNTIF(P18:V18,Versiones!$G$3)>0, COUNTIF(P18:V18,Versiones!$H$3)>0), "Sprint 16",TRUE, "")} -> Sprint 16 | AF18: ="v"&MAX( IFERROR(VALUE(MID(Jira__32[[#This Row],[Versiones corregidas]],2,99)),0), IFERROR(VALUE(MID(Jira__32[[#This Row],[Versiones corregidas_13]],2,99)),0), IFERROR(VALUE(MID(Jira__32[[#This Row],[Versiones corregidas_14]],2,99)),0) ) -> v0.5 | AG18: {=_xlfn.IFS(Jira__32[[#This Row],[¿En qué versión fue corregido?]]="v0","N/A",Jira__32[[#This Row],[¿En qué versión fue corregido?]]="v0.4","Sprint 16", Jira__32[[#This Row],[¿En qué versión fue corregido?]]="v0.5","Sprint 17", Jira__32[[#This Row],[¿En qué versión fue corregido?]]="v0.6","Sprint 18", Jira__32[[#This Row],[¿En qué versión fue corregido?]]="v0.7","Sprint 19", Jira__32[[#This Row],[¿En qué versión fue corregido?]]="v0.8","Sprint 20",Jira__32[[#This Row],[¿En qué versión fue corregido?]]="v0.9","Sprint 21", TRUE,"Desconocido")} -> Sprint 17 | AH18: {=_xlfn.IFS(COUNTIF(P18:V18, Versiones!$A$13)>0, "Funcional", COUNTIF(P18:V18, Versiones!$A$14)>0, "Configuración", COUNTIF(P18:V18, Versiones!$A$15)>0, "Look&Feel", COUNTIF(P18:V18, Versiones!$A$16)>0, "Integración", COUNTIF(P18:V18, Versiones!$A$17)>0, "Contenido/Datos", COUNTIF(P18:V18, Versiones!$A$18)>0, "Eventos_Cosmos", COUNTIF(P18:V18, Versiones!$A$19)>0, "Eventos_iOT", COUNTIF(P18:V18, Versiones!$A$20)>0, "Eventos_Fabric", TRUE, "No encontrado")} -> Funcional
A19: Error | B19: T20-935 | C19: 83020 | D19: POS - El shortcut F7 inicia el flujo de devoluciones | E19: 87100 | F19: T20-1091 | G19: 4.- QA | H19: Medio | I19: READY FOR UAT | J19: T20 Sprint 17 2025 | K19: T20 Sprint 18 2025 | L19: Backlog BUGS | P19: Funcional | Q19: QA-SmokeV0.4 | W19: Ludo | X19: 45873.033 | Y19: v0.5 | AB19: =IF(LEFT(Jira__32[[#This Row],[Resumen]],3)="POS","POS",IF(LEFT(Jira__32[[#This Row],[Resumen]],3)="BOT","BOT","")) -> POS | AC19: Ludovic Hern | AE19: {=_xlfn.IFS(OR(COUNTIF(P19:V19,Versiones!$G$9)>0, COUNTIF(P19:V19,Versiones!$H$8)>0), "Sprint 21",OR(COUNTIF(P19:V19,Versiones!$G$8)>0, COUNTIF(P19:V19,Versiones!$H$8)>0, COUNTIF(P19:V19,Versiones!$I$8)>0), "Sprint 20",OR(COUNTIF(P19:V19,Versiones!$G$7)>0, COUNTIF(P19:V19,Versiones!$H$7)>0, COUNTIF(P19:V19,Versiones!$I$7)>0), "Sprint 19",OR(COUNTIF(P19:V19,Versiones!$G$6)>0, COUNTIF(P19:V19,Versiones!$H$6)>0, COUNTIF(P19:V19,Versiones!$I$6)>0), "Sprint 18",OR(COUNTIF(P19:V19,Versiones!$G$4)>0, COUNTIF(P19:V19,Versiones!$H$4)>0, COUNTIF(P19:V19,Versiones!$G$5)>0, COUNTIF(P19:V19,Versiones!$H$5)>0), "Sprint 17",OR(COUNTIF(P19:V19,Versiones!$G$2)>0, COUNTIF(P19:V19,Versiones!$H$2)>0, COUNTIF(P19:V19,Versiones!$G$3)>0, COUNTIF(P19:V19,Versiones!$H$3)>0), "Sprint 16", OR(COUNTIF(P19:V19,Versiones!$G$2)>0, COUNTIF(P19:V19,Versiones!$H$2)>0, COUNTIF(P19:V19,Versiones!$G$3)>0, COUNTIF(P19:V19,Versiones!$H$3)>0), "Sprint 16",TRUE, "")} -> Sprint 16 | AF19: ="v"&MAX( IFERROR(VALUE(MID(Jira__32[[#This Row],[Versiones corregidas]],2,99)),0), IFERROR(VALUE(MID(Jira__32[[#This Row],[Versiones corregidas_13]],2,99)),0), IFERROR(VALUE(MID(Jira__32[[#This Row],[Versiones corregidas_14]],2,99)),0) ) -> v0.5 | AG19: {=_xlfn.IFS(Jira__32[[#This Row],[¿En qué versión fue corregido?]]="v0","N/A",Jira__32[[#This Row],[¿En qué versión fue corregido?]]="v0.4","Sprint 16", Jira__32[[#This Row],[¿En qué versión fue corregido?]]="v0.5","Sprint 17", Jira__32[[#This Row],[¿En qué versión fue corregido?]]="v0.6","Sprint 18", Jira__32[[#This Row],[¿En qué versión fue corregido?]]="v0.7","Sprint 19", Jira__32[[#This Row],[¿En qué versión fue corregido?]]="v0.8","Sprint 20",Jira__32[[#This Row],[¿En qué versión fue corregido?]]="v0.9","Sprint 21", TRUE,"Desconocido")} -> Sprint 17 | AH19: {=_xlfn.IFS(COUNTIF(P19:V19, Versiones!$A$13)>0, "Funcional", COUNTIF(P19:V19, Versiones!$A$14)>0, "Configuración", COUNTIF(P19:V19, Versiones!$A$15)>0, "Look&Feel", COUNTIF(P19:V19, Versiones!$A$16)>0, "Integración", COUNTIF(P19:V19, Versiones!$A$17)>0, "Contenido/Datos", COUNTIF(P19:V19, Versiones!$A$18)>0, "Eventos_Cosmos", COUNTIF(P19:V19, Versiones!$A$19)>0, "Eventos_iOT", COUNTIF(P19:V19, Versiones!$A$20)>0, "Eventos_Fabric", TRUE, "No encontrado")} -> Funcional
A20: Error | B20: T20-933 | C20: 83017 | D20: POS - Shortcut F9 inicia flujo de pago de servicio | E20: 87100 | F20: T20-1091 | G20: 4.- QA | H20: Medio | I20: READY FOR UAT | J20: T20 Sprint 19 2025 | K20: Backlog BUGS | P20: Funcional | Q20: QA-SmokeV0.4 | R20: T3B20_POS | S20: Tienda2.0 | W20: Ludo | X20: 45873.026 | Y20: v0.7 | AB20: =IF(LEFT(Jira__32[[#This Row],[Resumen]],3)="POS","POS",IF(LEFT(Jira__32[[#This Row],[Resumen]],3)="BOT","BOT","")) -> POS | AC20: PENDIENTES | AE20: {=_xlfn.IFS(OR(COUNTIF(P20:V20,Versiones!$G$9)>0, COUNTIF(P20:V20,Versiones!$H$8)>0), "Sprint 21",OR(COUNTIF(P20:V20,Versiones!$G$8)>0, COUNTIF(P20:V20,Versiones!$H$8)>0, COUNTIF(P20:V20,Versiones!$I$8)>0), "Sprint 20",OR(COUNTIF(P20:V20,Versiones!$G$7)>0, COUNTIF(P20:V20,Versiones!$H$7)>0, COUNTIF(P20:V20,Versiones!$I$7)>0), "Sprint 19",OR(COUNTIF(P20:V20,Versiones!$G$6)>0, COUNTIF(P20:V20,Versiones!$H$6)>0, COUNTIF(P20:V20,Versiones!$I$6)>0), "Sprint 18",OR(COUNTIF(P20:V20,Versiones!$G$4)>0, COUNTIF(P20:V20,Versiones!$H$4)>0, COUNTIF(P20:V20,Versiones!$G$5)>0, COUNTIF(P20:V20,Versiones!$H$5)>0), "Sprint 17",OR(COUNTIF(P20:V20,Versiones!$G$2)>0, COUNTIF(P20:V20,Versiones!$H$2)>0, COUNTIF(P20:V20,Versiones!$G$3)>0, COUNTIF(P20:V20,Versiones!$H$3)>0), "Sprint 16", OR(COUNTIF(P20:V20,Versiones!$G$2)>0, COUNTIF(P20:V20,Versiones!$H$2)>0, COUNTIF(P20:V20,Versiones!$G$3)>0, COUNTIF(P20:V20,Versiones!$H$3)>0), "Sprint 16",TRUE, "")} -> Sprint 16 | AF20: ="v"&MAX( IFERROR(VALUE(MID(Jira__32[[#This Row],[Versiones corregidas]],2,99)),0), IFERROR(VALUE(MID(Jira__32[[#This Row],[Versiones corregidas_13]],2,99)),0), IFERROR(VALUE(MID(Jira__32[[#This Row],[Versiones corregidas_14]],2,99)),0) ) -> v0.7 | AG20: {=_xlfn.IFS(Jira__32[[#This Row],[¿En qué versión fue corregido?]]="v0","N/A",Jira__32[[#This Row],[¿En qué versión fue corregido?]]="v0.4","Sprint 16", Jira__32[[#This Row],[¿En qué versión fue corregido?]]="v0.5","Sprint 17", Jira__32[[#This Row],[¿En qué versión fue corregido?]]="v0.6","Sprint 18", Jira__32[[#This Row],[¿En qué versión fue corregido?]]="v0.7","Sprint 19", Jira__32[[#This Row],[¿En qué versión fue corregido?]]="v0.8","Sprint 20",Jira__32[[#This Row],[¿En qué versión fue corregido?]]="v0.9","Sprint 21", TRUE,"Desconocido")} -> Sprint 19 | AH20: {=_xlfn.IFS(COUNTIF(P20:V20, Versiones!$A$13)>0, "Funcional", COUNTIF(P20:V20, Versiones!$A$14)>0, "Configuración", COUNTIF(P20:V20, Versiones!$A$15)>0, "Look&Feel", COUNTIF(P20:V20, Versiones!$A$16)>0, "Integración", COUNTIF(P20:V20, Versiones!$A$17)>0, "Contenido/Datos", COUNTIF(P20:V20, Versiones!$A$18)>0, "Eventos_Cosmos", COUNTIF(P20:V20, Versiones!$A$19)>0, "Eventos_iOT", COUNTIF(P20:V20, Versiones!$A$20)>0, "Eventos_Fabric", TRUE, "No encontrado")} -> Funcional
